[03/Oct/2018 15:11:37] "GET / HTTP/1.1" 200 1137
Not Found: /favicon.ico
[03/Oct/2018 15:11:38] "GET /favicon.ico HTTP/1.1" 404 2549
[03/Oct/2018 15:12:32] "GET / HTTP/1.1" 200 1137
[03/Oct/2018 15:12:33] "GET / HTTP/1.1" 200 1137
[03/Oct/2018 15:12:54] "GET / HTTP/1.1" 200 1137
[03/Oct/2018 15:13:45] "GET / HTTP/1.1" 200 1137
[03/Oct/2018 15:14:26] "GET /hello-world.txt HTTP/1.1" 200 11
[03/Oct/2018 15:14:32] "GET /hello-world.txt HTTP/1.1" 200 11
[03/Oct/2018 15:14:34] "GET / HTTP/1.1" 200 1137
[03/Oct/2018 15:14:40] "GET /image.jpg HTTP/1.1" 200 11
Invalid HTTP_HOST header: '1.2.3.4:1234'. You may need to add '1.2.3.4' to ALLOWED_HOSTS.
Bad Request: /
[03/Oct/2018 17:52:27] "POST / HTTP/1.1" 400 61092
[03/Oct/2018 18:47:56] "GET /image.jpg HTTP/1.1" 200 11
[03/Oct/2018 20:10:04] "GET /image.jpg HTTP/1.1" 200 11
[03/Oct/2018 20:16:10] "GET /image.jpg HTTP/1.1" 200 11
[03/Oct/2018 20:16:41] "GET /image.jpg HTTP/1.1" 200 11
[03/Oct/2018 20:16:42] "GET / HTTP/1.1" 200 1137
[03/Oct/2018 20:16:44] "GET / HTTP/1.1" 200 1137
[03/Oct/2018 20:16:44] "GET /api HTTP/1.1" 301 0
[03/Oct/2018 20:16:44] "GET /api/ HTTP/1.1" 200 5284
[03/Oct/2018 20:16:44] "GET /static/rest_framework/css/prettify.css HTTP/1.1" 200 817
[03/Oct/2018 20:16:44] "GET /static/rest_framework/css/default.css HTTP/1.1" 200 1131
[03/Oct/2018 20:16:44] "GET /static/rest_framework/css/bootstrap-tweaks.css HTTP/1.1" 200 3385
[03/Oct/2018 20:16:45] "GET /static/rest_framework/css/bootstrap.min.css HTTP/1.1" 200 121200
[03/Oct/2018 20:16:45] "GET /static/rest_framework/js/jquery-3.3.1.min.js HTTP/1.1" 200 86927
[03/Oct/2018 20:16:45] "GET /static/rest_framework/js/ajax-form.js HTTP/1.1" 200 3597
[03/Oct/2018 20:16:45] "GET /static/rest_framework/js/bootstrap.min.js HTTP/1.1" 200 37045
[03/Oct/2018 20:16:45] "GET /static/rest_framework/js/csrf.js HTTP/1.1" 200 1735
[03/Oct/2018 20:16:45] "GET /static/rest_framework/js/prettify-min.js HTTP/1.1" 200 13632
[03/Oct/2018 20:16:45] "GET /static/rest_framework/js/default.js HTTP/1.1" 200 1262
[03/Oct/2018 20:16:45] "GET /static/rest_framework/img/grid.png HTTP/1.1" 200 1458
Performing system checks...

System check identified no issues (0 silenced).
October 03, 2018 - 15:12:49
Django version 2.1.1, using settings 'webresume.settings'
Starting development server at http://0.0.0.0:8000/
Quit the server with CONTROL-C.
[03/Oct/2018 20:23:43] "GET / HTTP/1.1" 200 1137
[03/Oct/2018 20:23:47] "GET / HTTP/1.1" 200 1137
[03/Oct/2018 20:23:48] "GET / HTTP/1.1" 200 1137
[03/Oct/2018 20:23:50] "GET / HTTP/1.1" 200 1137
Internal Server Error: /image.jpg
Traceback (most recent call last):
  File "/home/ubuntu/assignment3/env/lib/python3.5/site-packages/django/core/handlers/exception.py", line 34, in inner
    response = get_response(request)
  File "/home/ubuntu/assignment3/env/lib/python3.5/site-packages/django/core/handlers/base.py", line 126, in _get_response
    response = self.process_exception_by_middleware(e, request)
  File "/home/ubuntu/assignment3/env/lib/python3.5/site-packages/django/core/handlers/base.py", line 124, in _get_response
    response = wrapped_callback(request, *callback_args, **callback_kwargs)
  File "/home/ubuntu/assignment3/web-app-ci-cd-with-travis-ci-dong-alex/webresume/frontend/views.py", line 19, in image_file
    return HttpResponse(base64.b64decode(request), content_type="image/jpeg")
  File "/usr/lib/python3.5/base64.py", line 81, in b64decode
    s = _bytes_from_decode_data(s)
  File "/usr/lib/python3.5/base64.py", line 46, in _bytes_from_decode_data
    "string, not %r" % s.__class__.__name__) from None
TypeError: argument should be a bytes-like object or ASCII string, not 'WSGIRequest'
[03/Oct/2018 20:23:56] "GET /image.jpg HTTP/1.1" 500 134797
Internal Server Error: /image.jpg
Traceback (most recent call last):
  File "/home/ubuntu/assignment3/env/lib/python3.5/site-packages/django/core/handlers/exception.py", line 34, in inner
    response = get_response(request)
  File "/home/ubuntu/assignment3/env/lib/python3.5/site-packages/django/core/handlers/base.py", line 126, in _get_response
    response = self.process_exception_by_middleware(e, request)
  File "/home/ubuntu/assignment3/env/lib/python3.5/site-packages/django/core/handlers/base.py", line 124, in _get_response
    response = wrapped_callback(request, *callback_args, **callback_kwargs)
  File "/home/ubuntu/assignment3/web-app-ci-cd-with-travis-ci-dong-alex/webresume/frontend/views.py", line 19, in image_file
    return HttpResponse(base64.b64decode(request), content_type="image/jpeg")
  File "/usr/lib/python3.5/base64.py", line 81, in b64decode
    s = _bytes_from_decode_data(s)
  File "/usr/lib/python3.5/base64.py", line 46, in _bytes_from_decode_data
    "string, not %r" % s.__class__.__name__) from None
TypeError: argument should be a bytes-like object or ASCII string, not 'WSGIRequest'
[03/Oct/2018 20:23:57] "GET /image.jpg HTTP/1.1" 500 134797
Performing system checks...

System check identified no issues (0 silenced).
October 03, 2018 - 20:23:35
Django version 2.1.1, using settings 'webresume.settings'
Starting development server at http://0.0.0.0:8000/
Quit the server with CONTROL-C.
Internal Server Error: /image.jpg
Traceback (most recent call last):
  File "/home/ubuntu/assignment3/env/lib/python3.5/site-packages/django/core/handlers/exception.py", line 34, in inner
    response = get_response(request)
  File "/home/ubuntu/assignment3/env/lib/python3.5/site-packages/django/core/handlers/base.py", line 126, in _get_response
    response = self.process_exception_by_middleware(e, request)
  File "/home/ubuntu/assignment3/env/lib/python3.5/site-packages/django/core/handlers/base.py", line 124, in _get_response
    response = wrapped_callback(request, *callback_args, **callback_kwargs)
  File "/home/ubuntu/assignment3/web-app-ci-cd-with-travis-ci-dong-alex/webresume/frontend/views.py", line 19, in image_file
    return HttpResponse(base64.b64encode(request), content_type="image/jpeg")
  File "/usr/lib/python3.5/base64.py", line 59, in b64encode
    encoded = binascii.b2a_base64(s)[:-1]
TypeError: a bytes-like object is required, not 'WSGIRequest'
[03/Oct/2018 20:24:22] "GET /image.jpg HTTP/1.1" 500 126778
Performing system checks...

System check identified no issues (0 silenced).
October 03, 2018 - 20:24:21
Django version 2.1.1, using settings 'webresume.settings'
Starting development server at http://0.0.0.0:8000/
Quit the server with CONTROL-C.
Internal Server Error: /image.jpg
Traceback (most recent call last):
  File "/home/ubuntu/assignment3/env/lib/python3.5/site-packages/django/core/handlers/exception.py", line 34, in inner
    response = get_response(request)
  File "/home/ubuntu/assignment3/env/lib/python3.5/site-packages/django/core/handlers/base.py", line 126, in _get_response
    response = self.process_exception_by_middleware(e, request)
  File "/home/ubuntu/assignment3/env/lib/python3.5/site-packages/django/core/handlers/base.py", line 124, in _get_response
    response = wrapped_callback(request, *callback_args, **callback_kwargs)
  File "/home/ubuntu/assignment3/web-app-ci-cd-with-travis-ci-dong-alex/webresume/frontend/views.py", line 19, in image_file
    return HttpResponse(str(base64.b64decode(request)), content_type="image/jpeg")
  File "/usr/lib/python3.5/base64.py", line 81, in b64decode
    s = _bytes_from_decode_data(s)
  File "/usr/lib/python3.5/base64.py", line 46, in _bytes_from_decode_data
    "string, not %r" % s.__class__.__name__) from None
TypeError: argument should be a bytes-like object or ASCII string, not 'WSGIRequest'
[03/Oct/2018 20:26:58] "GET /image.jpg HTTP/1.1" 500 134807
Performing system checks...

System check identified no issues (0 silenced).
October 03, 2018 - 20:26:52
Django version 2.1.1, using settings 'webresume.settings'
Starting development server at http://0.0.0.0:8000/
Quit the server with CONTROL-C.
Internal Server Error: /image.jpg
Traceback (most recent call last):
  File "/home/ubuntu/assignment3/env/lib/python3.5/site-packages/django/core/handlers/exception.py", line 34, in inner
    response = get_response(request)
  File "/home/ubuntu/assignment3/env/lib/python3.5/site-packages/django/core/handlers/base.py", line 126, in _get_response
    response = self.process_exception_by_middleware(e, request)
  File "/home/ubuntu/assignment3/env/lib/python3.5/site-packages/django/core/handlers/base.py", line 124, in _get_response
    response = wrapped_callback(request, *callback_args, **callback_kwargs)
  File "/home/ubuntu/assignment3/web-app-ci-cd-with-travis-ci-dong-alex/webresume/frontend/views.py", line 19, in image_file
    return HttpResponse(str(b64decode(request)), content_type="image/jpeg")
NameError: name 'b64decode' is not defined
[03/Oct/2018 20:29:08] "GET /image.jpg HTTP/1.1" 500 122925
Performing system checks...

System check identified no issues (0 silenced).
October 03, 2018 - 20:29:05
Django version 2.1.1, using settings 'webresume.settings'
Starting development server at http://0.0.0.0:8000/
Quit the server with CONTROL-C.
Internal Server Error: /image.jpg
Traceback (most recent call last):
  File "/home/ubuntu/assignment3/env/lib/python3.5/site-packages/django/core/handlers/exception.py", line 34, in inner
    response = get_response(request)
  File "/home/ubuntu/assignment3/env/lib/python3.5/site-packages/django/core/handlers/base.py", line 126, in _get_response
    response = self.process_exception_by_middleware(e, request)
  File "/home/ubuntu/assignment3/env/lib/python3.5/site-packages/django/core/handlers/base.py", line 124, in _get_response
    response = wrapped_callback(request, *callback_args, **callback_kwargs)
  File "/home/ubuntu/assignment3/web-app-ci-cd-with-travis-ci-dong-alex/webresume/frontend/views.py", line 19, in image_file
    return HttpResponse(str(bas64.b64decode(request)), content_type="image/jpeg")
NameError: name 'bas64' is not defined
[03/Oct/2018 20:30:41] "GET /image.jpg HTTP/1.1" 500 122921
Internal Server Error: /image.jpg
Traceback (most recent call last):
  File "/home/ubuntu/assignment3/env/lib/python3.5/site-packages/django/core/handlers/exception.py", line 34, in inner
    response = get_response(request)
  File "/home/ubuntu/assignment3/env/lib/python3.5/site-packages/django/core/handlers/base.py", line 126, in _get_response
    response = self.process_exception_by_middleware(e, request)
  File "/home/ubuntu/assignment3/env/lib/python3.5/site-packages/django/core/handlers/base.py", line 124, in _get_response
    response = wrapped_callback(request, *callback_args, **callback_kwargs)
  File "/home/ubuntu/assignment3/web-app-ci-cd-with-travis-ci-dong-alex/webresume/frontend/views.py", line 19, in image_file
    return HttpResponse(str(bas64.b64decode(request)), content_type="image/jpeg")
NameError: name 'bas64' is not defined
[03/Oct/2018 20:30:44] "GET /image.jpg HTTP/1.1" 500 122921
Performing system checks...

System check identified no issues (0 silenced).
October 03, 2018 - 20:30:41
Django version 2.1.1, using settings 'webresume.settings'
Starting development server at http://0.0.0.0:8000/
Quit the server with CONTROL-C.
Performing system checks...

System check identified no issues (0 silenced).
October 03, 2018 - 20:30:59
Django version 2.1.1, using settings 'webresume.settings'
Starting development server at http://0.0.0.0:8000/
Quit the server with CONTROL-C.
Internal Server Error: /image.jpg
Traceback (most recent call last):
  File "/home/ubuntu/assignment3/env/lib/python3.5/site-packages/django/core/handlers/exception.py", line 34, in inner
    response = get_response(request)
  File "/home/ubuntu/assignment3/env/lib/python3.5/site-packages/django/core/handlers/base.py", line 126, in _get_response
    response = self.process_exception_by_middleware(e, request)
  File "/home/ubuntu/assignment3/env/lib/python3.5/site-packages/django/core/handlers/base.py", line 124, in _get_response
    response = wrapped_callback(request, *callback_args, **callback_kwargs)
  File "/home/ubuntu/assignment3/web-app-ci-cd-with-travis-ci-dong-alex/webresume/frontend/views.py", line 19, in image_file
    return HttpResponse(str(base64.b64decode(request)), content_type="image/jpeg")
  File "/usr/lib/python3.5/base64.py", line 81, in b64decode
    s = _bytes_from_decode_data(s)
  File "/usr/lib/python3.5/base64.py", line 46, in _bytes_from_decode_data
    "string, not %r" % s.__class__.__name__) from None
TypeError: argument should be a bytes-like object or ASCII string, not 'WSGIRequest'
[03/Oct/2018 20:31:05] "GET /image.jpg HTTP/1.1" 500 134807
Performing system checks...

System check identified no issues (0 silenced).
October 03, 2018 - 20:31:04
Django version 2.1.1, using settings 'webresume.settings'
Starting development server at http://0.0.0.0:8000/
Quit the server with CONTROL-C.
Internal Server Error: /image.jpg
Traceback (most recent call last):
  File "/home/ubuntu/assignment3/env/lib/python3.5/site-packages/django/core/handlers/exception.py", line 34, in inner
    response = get_response(request)
  File "/home/ubuntu/assignment3/env/lib/python3.5/site-packages/django/core/handlers/base.py", line 126, in _get_response
    response = self.process_exception_by_middleware(e, request)
  File "/home/ubuntu/assignment3/env/lib/python3.5/site-packages/django/core/handlers/base.py", line 124, in _get_response
    response = wrapped_callback(request, *callback_args, **callback_kwargs)
  File "/home/ubuntu/assignment3/web-app-ci-cd-with-travis-ci-dong-alex/webresume/frontend/views.py", line 19, in image_file
    return HttpResponse(base64.b64decode(request), content_type="image/jpeg")
  File "/usr/lib/python3.5/base64.py", line 81, in b64decode
    s = _bytes_from_decode_data(s)
  File "/usr/lib/python3.5/base64.py", line 46, in _bytes_from_decode_data
    "string, not %r" % s.__class__.__name__) from None
TypeError: argument should be a bytes-like object or ASCII string, not 'WSGIRequest'
[03/Oct/2018 20:34:10] "GET /image.jpg HTTP/1.1" 500 134797
Internal Server Error: /image.jpg
Traceback (most recent call last):
  File "/home/ubuntu/assignment3/env/lib/python3.5/site-packages/django/core/handlers/exception.py", line 34, in inner
    response = get_response(request)
  File "/home/ubuntu/assignment3/env/lib/python3.5/site-packages/django/core/handlers/base.py", line 126, in _get_response
    response = self.process_exception_by_middleware(e, request)
  File "/home/ubuntu/assignment3/env/lib/python3.5/site-packages/django/core/handlers/base.py", line 124, in _get_response
    response = wrapped_callback(request, *callback_args, **callback_kwargs)
  File "/home/ubuntu/assignment3/web-app-ci-cd-with-travis-ci-dong-alex/webresume/frontend/views.py", line 19, in image_file
    return HttpResponse(base64.b64decode(request), content_type="image/jpeg")
  File "/usr/lib/python3.5/base64.py", line 81, in b64decode
    s = _bytes_from_decode_data(s)
  File "/usr/lib/python3.5/base64.py", line 46, in _bytes_from_decode_data
    "string, not %r" % s.__class__.__name__) from None
TypeError: argument should be a bytes-like object or ASCII string, not 'WSGIRequest'
[03/Oct/2018 20:34:12] "GET /image.jpg HTTP/1.1" 500 134797
Performing system checks...

System check identified no issues (0 silenced).
October 03, 2018 - 20:33:49
Django version 2.1.1, using settings 'webresume.settings'
Starting development server at http://0.0.0.0:8000/
Quit the server with CONTROL-C.
Internal Server Error: /image.jpg
Traceback (most recent call last):
  File "/home/ubuntu/assignment3/env/lib/python3.5/site-packages/django/core/handlers/exception.py", line 34, in inner
    response = get_response(request)
  File "/home/ubuntu/assignment3/env/lib/python3.5/site-packages/django/core/handlers/base.py", line 126, in _get_response
    response = self.process_exception_by_middleware(e, request)
  File "/home/ubuntu/assignment3/env/lib/python3.5/site-packages/django/core/handlers/base.py", line 124, in _get_response
    response = wrapped_callback(request, *callback_args, **callback_kwargs)
  File "/home/ubuntu/assignment3/web-app-ci-cd-with-travis-ci-dong-alex/webresume/frontend/views.py", line 19, in image_file
    return HttpResponse(base64.b64decode(request), content_type="image/jpeg")
  File "/usr/lib/python3.5/base64.py", line 81, in b64decode
    s = _bytes_from_decode_data(s)
  File "/usr/lib/python3.5/base64.py", line 46, in _bytes_from_decode_data
    "string, not %r" % s.__class__.__name__) from None
TypeError: argument should be a bytes-like object or ASCII string, not 'WSGIRequest'
[03/Oct/2018 20:34:17] "GET /image.jpg HTTP/1.1" 500 134797
Internal Server Error: /image.jpg
Traceback (most recent call last):
  File "/home/ubuntu/assignment3/env/lib/python3.5/site-packages/django/core/handlers/exception.py", line 34, in inner
    response = get_response(request)
  File "/home/ubuntu/assignment3/env/lib/python3.5/site-packages/django/core/handlers/base.py", line 126, in _get_response
    response = self.process_exception_by_middleware(e, request)
  File "/home/ubuntu/assignment3/env/lib/python3.5/site-packages/django/core/handlers/base.py", line 124, in _get_response
    response = wrapped_callback(request, *callback_args, **callback_kwargs)
  File "/home/ubuntu/assignment3/web-app-ci-cd-with-travis-ci-dong-alex/webresume/frontend/views.py", line 19, in image_file
    return HttpResponse(base64.b64decode(request), content_type="image/jpeg")
  File "/usr/lib/python3.5/base64.py", line 81, in b64decode
    s = _bytes_from_decode_data(s)
  File "/usr/lib/python3.5/base64.py", line 46, in _bytes_from_decode_data
    "string, not %r" % s.__class__.__name__) from None
TypeError: argument should be a bytes-like object or ASCII string, not 'WSGIRequest'
[03/Oct/2018 20:34:18] "GET /image.jpg HTTP/1.1" 500 134797
Internal Server Error: /image.jpg
Traceback (most recent call last):
  File "/home/ubuntu/assignment3/env/lib/python3.5/site-packages/django/core/handlers/exception.py", line 34, in inner
    response = get_response(request)
  File "/home/ubuntu/assignment3/env/lib/python3.5/site-packages/django/core/handlers/base.py", line 126, in _get_response
    response = self.process_exception_by_middleware(e, request)
  File "/home/ubuntu/assignment3/env/lib/python3.5/site-packages/django/core/handlers/base.py", line 124, in _get_response
    response = wrapped_callback(request, *callback_args, **callback_kwargs)
  File "/home/ubuntu/assignment3/web-app-ci-cd-with-travis-ci-dong-alex/webresume/frontend/views.py", line 19, in image_file
    return HttpResponse(base64.b64decode(request), content_type="image/jpeg")
  File "/usr/lib/python3.5/base64.py", line 81, in b64decode
    s = _bytes_from_decode_data(s)
  File "/usr/lib/python3.5/base64.py", line 46, in _bytes_from_decode_data
    "string, not %r" % s.__class__.__name__) from None
TypeError: argument should be a bytes-like object or ASCII string, not 'WSGIRequest'
[03/Oct/2018 20:34:20] "GET /image.jpg HTTP/1.1" 500 134797
Internal Server Error: /image.jpg
Traceback (most recent call last):
  File "/home/ubuntu/assignment3/env/lib/python3.5/site-packages/django/core/handlers/exception.py", line 34, in inner
    response = get_response(request)
  File "/home/ubuntu/assignment3/env/lib/python3.5/site-packages/django/core/handlers/base.py", line 126, in _get_response
    response = self.process_exception_by_middleware(e, request)
  File "/home/ubuntu/assignment3/env/lib/python3.5/site-packages/django/core/handlers/base.py", line 124, in _get_response
    response = wrapped_callback(request, *callback_args, **callback_kwargs)
  File "/home/ubuntu/assignment3/web-app-ci-cd-with-travis-ci-dong-alex/webresume/frontend/views.py", line 19, in image_file
    return HttpResponse(base64.b64decode(request), content_type="image/jpeg")
  File "/usr/lib/python3.5/base64.py", line 81, in b64decode
    s = _bytes_from_decode_data(s)
  File "/usr/lib/python3.5/base64.py", line 46, in _bytes_from_decode_data
    "string, not %r" % s.__class__.__name__) from None
TypeError: argument should be a bytes-like object or ASCII string, not 'WSGIRequest'
[03/Oct/2018 20:34:21] "GET /image.jpg HTTP/1.1" 500 134797
Performing system checks...

System check identified no issues (0 silenced).
October 03, 2018 - 20:34:17
Django version 2.1.1, using settings 'webresume.settings'
Starting development server at http://0.0.0.0:8000/
Quit the server with CONTROL-C.
Internal Server Error: /image.jpg
Traceback (most recent call last):
  File "/home/ubuntu/assignment3/env/lib/python3.5/site-packages/django/core/handlers/exception.py", line 34, in inner
    response = get_response(request)
  File "/home/ubuntu/assignment3/env/lib/python3.5/site-packages/django/core/handlers/base.py", line 126, in _get_response
    response = self.process_exception_by_middleware(e, request)
  File "/home/ubuntu/assignment3/env/lib/python3.5/site-packages/django/core/handlers/base.py", line 124, in _get_response
    response = wrapped_callback(request, *callback_args, **callback_kwargs)
  File "/home/ubuntu/assignment3/web-app-ci-cd-with-travis-ci-dong-alex/webresume/frontend/views.py", line 20, in image_file
    return HttpResponse(base64.b64decode(request), content_type="image/jpeg")
  File "/usr/lib/python3.5/base64.py", line 81, in b64decode
    s = _bytes_from_decode_data(s)
  File "/usr/lib/python3.5/base64.py", line 46, in _bytes_from_decode_data
    "string, not %r" % s.__class__.__name__) from None
TypeError: argument should be a bytes-like object or ASCII string, not 'WSGIRequest'
[03/Oct/2018 20:34:42] "GET /image.jpg HTTP/1.1" 500 134776
Internal Server Error: /image.jpg
Traceback (most recent call last):
  File "/home/ubuntu/assignment3/env/lib/python3.5/site-packages/django/core/handlers/exception.py", line 34, in inner
    response = get_response(request)
  File "/home/ubuntu/assignment3/env/lib/python3.5/site-packages/django/core/handlers/base.py", line 126, in _get_response
    response = self.process_exception_by_middleware(e, request)
  File "/home/ubuntu/assignment3/env/lib/python3.5/site-packages/django/core/handlers/base.py", line 124, in _get_response
    response = wrapped_callback(request, *callback_args, **callback_kwargs)
  File "/home/ubuntu/assignment3/web-app-ci-cd-with-travis-ci-dong-alex/webresume/frontend/views.py", line 20, in image_file
    return HttpResponse(base64.b64decode(request), content_type="image/jpeg")
  File "/usr/lib/python3.5/base64.py", line 81, in b64decode
    s = _bytes_from_decode_data(s)
  File "/usr/lib/python3.5/base64.py", line 46, in _bytes_from_decode_data
    "string, not %r" % s.__class__.__name__) from None
TypeError: argument should be a bytes-like object or ASCII string, not 'WSGIRequest'
[03/Oct/2018 20:34:43] "GET /image.jpg HTTP/1.1" 500 134776
Performing system checks...

System check identified no issues (0 silenced).
October 03, 2018 - 20:34:41
Django version 2.1.1, using settings 'webresume.settings'
Starting development server at http://0.0.0.0:8000/
Quit the server with CONTROL-C.
<WSGIRequest: GET '/image.jpg'>
<WSGIRequest: GET '/image.jpg'>
Internal Server Error: /image.jpg
Traceback (most recent call last):
  File "/home/ubuntu/assignment3/env/lib/python3.5/site-packages/django/core/handlers/exception.py", line 34, in inner
    response = get_response(request)
  File "/home/ubuntu/assignment3/env/lib/python3.5/site-packages/django/core/handlers/base.py", line 126, in _get_response
    response = self.process_exception_by_middleware(e, request)
  File "/home/ubuntu/assignment3/env/lib/python3.5/site-packages/django/core/handlers/base.py", line 124, in _get_response
    response = wrapped_callback(request, *callback_args, **callback_kwargs)
  File "/home/ubuntu/assignment3/web-app-ci-cd-with-travis-ci-dong-alex/webresume/frontend/views.py", line 20, in image_file
    return HttpResponse(base64.b64decode(request), content_type="image/jpeg")
  File "/usr/lib/python3.5/base64.py", line 81, in b64decode
    s = _bytes_from_decode_data(s)
  File "/usr/lib/python3.5/base64.py", line 46, in _bytes_from_decode_data
    "string, not %r" % s.__class__.__name__) from None
TypeError: argument should be a bytes-like object or ASCII string, not 'WSGIRequest'
[03/Oct/2018 20:34:51] "GET /image.jpg HTTP/1.1" 500 134776
Internal Server Error: /image.jpg
Traceback (most recent call last):
  File "/home/ubuntu/assignment3/env/lib/python3.5/site-packages/django/core/handlers/exception.py", line 34, in inner
    response = get_response(request)
  File "/home/ubuntu/assignment3/env/lib/python3.5/site-packages/django/core/handlers/base.py", line 126, in _get_response
    response = self.process_exception_by_middleware(e, request)
  File "/home/ubuntu/assignment3/env/lib/python3.5/site-packages/django/core/handlers/base.py", line 124, in _get_response
    response = wrapped_callback(request, *callback_args, **callback_kwargs)
  File "/home/ubuntu/assignment3/web-app-ci-cd-with-travis-ci-dong-alex/webresume/frontend/views.py", line 20, in image_file
    return HttpResponse(base64.b64decode(request), content_type="image/jpeg")
  File "/usr/lib/python3.5/base64.py", line 81, in b64decode
    s = _bytes_from_decode_data(s)
  File "/usr/lib/python3.5/base64.py", line 46, in _bytes_from_decode_data
    "string, not %r" % s.__class__.__name__) from None
TypeError: argument should be a bytes-like object or ASCII string, not 'WSGIRequest'
[03/Oct/2018 20:34:52] "GET /image.jpg HTTP/1.1" 500 134776
Performing system checks...

System check identified no issues (0 silenced).
October 03, 2018 - 20:34:50
Django version 2.1.1, using settings 'webresume.settings'
Starting development server at http://0.0.0.0:8000/
Quit the server with CONTROL-C.
<WSGIRequest: GET '/image.jpg'>
<WSGIRequest: GET '/image.jpg'>
[03/Oct/2018 20:35:34] "GET /image.jpg HTTP/1.1" 200 0
[03/Oct/2018 20:35:36] "GET /image.jpg HTTP/1.1" 200 0
[03/Oct/2018 20:35:41] "GET /image.jpg HTTP/1.1" 200 0
[03/Oct/2018 20:35:56] "GET /image.jpg HTTP/1.1" 200 0
[03/Oct/2018 20:36:08] "GET /image.jpg HTTP/1.1" 200 0
[03/Oct/2018 20:38:53] "GET /image.jpg HTTP/1.1" 200 0
Performing system checks...

System check identified no issues (0 silenced).
October 03, 2018 - 20:35:33
Django version 2.1.1, using settings 'webresume.settings'
Starting development server at http://0.0.0.0:8000/
Quit the server with CONTROL-C.
Unhandled exception in thread started by <function check_errors.<locals>.wrapper at 0x7f28fd721620>
Traceback (most recent call last):
  File "/home/ubuntu/assignment3/env/lib/python3.5/site-packages/django/utils/autoreload.py", line 225, in wrapper
    fn(*args, **kwargs)
  File "/home/ubuntu/assignment3/env/lib/python3.5/site-packages/django/core/management/commands/runserver.py", line 117, in inner_run
    self.check(display_num_errors=True)
  File "/home/ubuntu/assignment3/env/lib/python3.5/site-packages/django/core/management/base.py", line 379, in check
    include_deployment_checks=include_deployment_checks,
  File "/home/ubuntu/assignment3/env/lib/python3.5/site-packages/django/core/management/base.py", line 366, in _run_checks
    return checks.run_checks(**kwargs)
  File "/home/ubuntu/assignment3/env/lib/python3.5/site-packages/django/core/checks/registry.py", line 71, in run_checks
    new_errors = check(app_configs=app_configs)
  File "/home/ubuntu/assignment3/env/lib/python3.5/site-packages/django/core/checks/urls.py", line 40, in check_url_namespaces_unique
    all_namespaces = _load_all_namespaces(resolver)
  File "/home/ubuntu/assignment3/env/lib/python3.5/site-packages/django/core/checks/urls.py", line 57, in _load_all_namespaces
    url_patterns = getattr(resolver, 'url_patterns', [])
  File "/home/ubuntu/assignment3/env/lib/python3.5/site-packages/django/utils/functional.py", line 37, in __get__
    res = instance.__dict__[self.name] = self.func(instance)
  File "/home/ubuntu/assignment3/env/lib/python3.5/site-packages/django/urls/resolvers.py", line 533, in url_patterns
    patterns = getattr(self.urlconf_module, "urlpatterns", self.urlconf_module)
  File "/home/ubuntu/assignment3/env/lib/python3.5/site-packages/django/utils/functional.py", line 37, in __get__
    res = instance.__dict__[self.name] = self.func(instance)
  File "/home/ubuntu/assignment3/env/lib/python3.5/site-packages/django/urls/resolvers.py", line 526, in urlconf_module
    return import_module(self.urlconf_name)
  File "/usr/lib/python3.5/importlib/__init__.py", line 126, in import_module
    return _bootstrap._gcd_import(name[level:], package, level)
  File "<frozen importlib._bootstrap>", line 986, in _gcd_import
  File "<frozen importlib._bootstrap>", line 969, in _find_and_load
  File "<frozen importlib._bootstrap>", line 958, in _find_and_load_unlocked
  File "<frozen importlib._bootstrap>", line 673, in _load_unlocked
  File "<frozen importlib._bootstrap_external>", line 665, in exec_module
  File "<frozen importlib._bootstrap>", line 222, in _call_with_frames_removed
  File "/home/ubuntu/assignment3/web-app-ci-cd-with-travis-ci-dong-alex/webresume/webresume/urls.py", line 22, in <module>
    path('', include('frontend.urls')),
  File "/home/ubuntu/assignment3/env/lib/python3.5/site-packages/django/urls/conf.py", line 34, in include
    urlconf_module = import_module(urlconf_module)
  File "/usr/lib/python3.5/importlib/__init__.py", line 126, in import_module
    return _bootstrap._gcd_import(name[level:], package, level)
  File "<frozen importlib._bootstrap>", line 986, in _gcd_import
  File "<frozen importlib._bootstrap>", line 969, in _find_and_load
  File "<frozen importlib._bootstrap>", line 958, in _find_and_load_unlocked
  File "<frozen importlib._bootstrap>", line 673, in _load_unlocked
  File "<frozen importlib._bootstrap_external>", line 665, in exec_module
  File "<frozen importlib._bootstrap>", line 222, in _call_with_frames_removed
  File "/home/ubuntu/assignment3/web-app-ci-cd-with-travis-ci-dong-alex/webresume/frontend/urls.py", line 2, in <module>
    from . import views
  File "/home/ubuntu/assignment3/web-app-ci-cd-with-travis-ci-dong-alex/webresume/frontend/views.py", line 20
    return HttpResponse(request, content_type="image/jpeg")
                                                          ^
SyntaxError: EOF while scanning triple-quoted string literal
Performing system checks...

Performing system checks...

System check identified no issues (0 silenced).
October 03, 2018 - 20:42:26
Django version 2.1.1, using settings 'webresume.settings'
Starting development server at http://0.0.0.0:8000/
Quit the server with CONTROL-C.
Internal Server Error: /image.jpg
Traceback (most recent call last):
  File "/home/ubuntu/assignment3/env/lib/python3.5/site-packages/django/core/handlers/exception.py", line 34, in inner
    response = get_response(request)
  File "/home/ubuntu/assignment3/env/lib/python3.5/site-packages/django/core/handlers/base.py", line 126, in _get_response
    response = self.process_exception_by_middleware(e, request)
  File "/home/ubuntu/assignment3/env/lib/python3.5/site-packages/django/core/handlers/base.py", line 124, in _get_response
    response = wrapped_callback(request, *callback_args, **callback_kwargs)
  File "/home/ubuntu/assignment3/web-app-ci-cd-with-travis-ci-dong-alex/webresume/frontend/views.py", line 20, in image_file
    final = base64.b64decode(request)
  File "/usr/lib/python3.5/base64.py", line 81, in b64decode
    s = _bytes_from_decode_data(s)
  File "/usr/lib/python3.5/base64.py", line 46, in _bytes_from_decode_data
    "string, not %r" % s.__class__.__name__) from None
TypeError: argument should be a bytes-like object or ASCII string, not 'WSGIRequest'
[03/Oct/2018 20:42:44] "GET /image.jpg HTTP/1.1" 500 134977
Performing system checks...

System check identified no issues (0 silenced).
October 03, 2018 - 20:42:43
Django version 2.1.1, using settings 'webresume.settings'
Starting development server at http://0.0.0.0:8000/
Quit the server with CONTROL-C.
Internal Server Error: /image.jpg
Traceback (most recent call last):
  File "/home/ubuntu/assignment3/env/lib/python3.5/site-packages/django/core/handlers/exception.py", line 34, in inner
    response = get_response(request)
  File "/home/ubuntu/assignment3/env/lib/python3.5/site-packages/django/core/handlers/base.py", line 126, in _get_response
    response = self.process_exception_by_middleware(e, request)
  File "/home/ubuntu/assignment3/env/lib/python3.5/site-packages/django/core/handlers/base.py", line 124, in _get_response
    response = wrapped_callback(request, *callback_args, **callback_kwargs)
  File "/home/ubuntu/assignment3/web-app-ci-cd-with-travis-ci-dong-alex/webresume/frontend/views.py", line 20, in image_file
    final = base64.b64decode(request).decode('utf-8')
  File "/usr/lib/python3.5/base64.py", line 81, in b64decode
    s = _bytes_from_decode_data(s)
  File "/usr/lib/python3.5/base64.py", line 46, in _bytes_from_decode_data
    "string, not %r" % s.__class__.__name__) from None
TypeError: argument should be a bytes-like object or ASCII string, not 'WSGIRequest'
[03/Oct/2018 20:48:54] "GET /image.jpg HTTP/1.1" 500 135025
Internal Server Error: /image.jpg
Traceback (most recent call last):
  File "/home/ubuntu/assignment3/env/lib/python3.5/site-packages/django/core/handlers/exception.py", line 34, in inner
    response = get_response(request)
  File "/home/ubuntu/assignment3/env/lib/python3.5/site-packages/django/core/handlers/base.py", line 126, in _get_response
    response = self.process_exception_by_middleware(e, request)
  File "/home/ubuntu/assignment3/env/lib/python3.5/site-packages/django/core/handlers/base.py", line 124, in _get_response
    response = wrapped_callback(request, *callback_args, **callback_kwargs)
  File "/home/ubuntu/assignment3/web-app-ci-cd-with-travis-ci-dong-alex/webresume/frontend/views.py", line 20, in image_file
    final = base64.b64decode(request).decode('utf-8')
  File "/usr/lib/python3.5/base64.py", line 81, in b64decode
    s = _bytes_from_decode_data(s)
  File "/usr/lib/python3.5/base64.py", line 46, in _bytes_from_decode_data
    "string, not %r" % s.__class__.__name__) from None
TypeError: argument should be a bytes-like object or ASCII string, not 'WSGIRequest'
[03/Oct/2018 20:48:55] "GET /image.jpg HTTP/1.1" 500 135025
Internal Server Error: /image.jpg
Traceback (most recent call last):
  File "/home/ubuntu/assignment3/env/lib/python3.5/site-packages/django/core/handlers/exception.py", line 34, in inner
    response = get_response(request)
  File "/home/ubuntu/assignment3/env/lib/python3.5/site-packages/django/core/handlers/base.py", line 126, in _get_response
    response = self.process_exception_by_middleware(e, request)
  File "/home/ubuntu/assignment3/env/lib/python3.5/site-packages/django/core/handlers/base.py", line 124, in _get_response
    response = wrapped_callback(request, *callback_args, **callback_kwargs)
  File "/home/ubuntu/assignment3/web-app-ci-cd-with-travis-ci-dong-alex/webresume/frontend/views.py", line 20, in image_file
    final = base64.b64decode(request).decode('utf-8')
  File "/usr/lib/python3.5/base64.py", line 81, in b64decode
    s = _bytes_from_decode_data(s)
  File "/usr/lib/python3.5/base64.py", line 46, in _bytes_from_decode_data
    "string, not %r" % s.__class__.__name__) from None
TypeError: argument should be a bytes-like object or ASCII string, not 'WSGIRequest'
[03/Oct/2018 20:48:56] "GET /image.jpg HTTP/1.1" 500 135025
Internal Server Error: /image.jpg
Traceback (most recent call last):
  File "/home/ubuntu/assignment3/env/lib/python3.5/site-packages/django/core/handlers/exception.py", line 34, in inner
    response = get_response(request)
  File "/home/ubuntu/assignment3/env/lib/python3.5/site-packages/django/core/handlers/base.py", line 126, in _get_response
    response = self.process_exception_by_middleware(e, request)
  File "/home/ubuntu/assignment3/env/lib/python3.5/site-packages/django/core/handlers/base.py", line 124, in _get_response
    response = wrapped_callback(request, *callback_args, **callback_kwargs)
  File "/home/ubuntu/assignment3/web-app-ci-cd-with-travis-ci-dong-alex/webresume/frontend/views.py", line 20, in image_file
    final = base64.b64decode(request).decode('utf-8')
  File "/usr/lib/python3.5/base64.py", line 81, in b64decode
    s = _bytes_from_decode_data(s)
  File "/usr/lib/python3.5/base64.py", line 46, in _bytes_from_decode_data
    "string, not %r" % s.__class__.__name__) from None
TypeError: argument should be a bytes-like object or ASCII string, not 'WSGIRequest'
[03/Oct/2018 20:48:56] "GET /image.jpg HTTP/1.1" 500 135025
Internal Server Error: /image.jpg
Traceback (most recent call last):
  File "/home/ubuntu/assignment3/env/lib/python3.5/site-packages/django/core/handlers/exception.py", line 34, in inner
    response = get_response(request)
  File "/home/ubuntu/assignment3/env/lib/python3.5/site-packages/django/core/handlers/base.py", line 126, in _get_response
    response = self.process_exception_by_middleware(e, request)
  File "/home/ubuntu/assignment3/env/lib/python3.5/site-packages/django/core/handlers/base.py", line 124, in _get_response
    response = wrapped_callback(request, *callback_args, **callback_kwargs)
  File "/home/ubuntu/assignment3/web-app-ci-cd-with-travis-ci-dong-alex/webresume/frontend/views.py", line 20, in image_file
    final = base64.b64decode(request).decode('utf-8')
  File "/usr/lib/python3.5/base64.py", line 81, in b64decode
    s = _bytes_from_decode_data(s)
  File "/usr/lib/python3.5/base64.py", line 46, in _bytes_from_decode_data
    "string, not %r" % s.__class__.__name__) from None
TypeError: argument should be a bytes-like object or ASCII string, not 'WSGIRequest'
[03/Oct/2018 20:48:56] "GET /image.jpg HTTP/1.1" 500 135025
Internal Server Error: /image.jpg
Traceback (most recent call last):
  File "/home/ubuntu/assignment3/env/lib/python3.5/site-packages/django/core/handlers/exception.py", line 34, in inner
    response = get_response(request)
  File "/home/ubuntu/assignment3/env/lib/python3.5/site-packages/django/core/handlers/base.py", line 126, in _get_response
    response = self.process_exception_by_middleware(e, request)
  File "/home/ubuntu/assignment3/env/lib/python3.5/site-packages/django/core/handlers/base.py", line 124, in _get_response
    response = wrapped_callback(request, *callback_args, **callback_kwargs)
  File "/home/ubuntu/assignment3/web-app-ci-cd-with-travis-ci-dong-alex/webresume/frontend/views.py", line 20, in image_file
    final = base64.b64decode(request).decode('utf-8')
  File "/usr/lib/python3.5/base64.py", line 81, in b64decode
    s = _bytes_from_decode_data(s)
  File "/usr/lib/python3.5/base64.py", line 46, in _bytes_from_decode_data
    "string, not %r" % s.__class__.__name__) from None
TypeError: argument should be a bytes-like object or ASCII string, not 'WSGIRequest'
[03/Oct/2018 20:48:57] "GET /image.jpg HTTP/1.1" 500 135025
Internal Server Error: /image.jpg
Traceback (most recent call last):
  File "/home/ubuntu/assignment3/env/lib/python3.5/site-packages/django/core/handlers/exception.py", line 34, in inner
    response = get_response(request)
  File "/home/ubuntu/assignment3/env/lib/python3.5/site-packages/django/core/handlers/base.py", line 126, in _get_response
    response = self.process_exception_by_middleware(e, request)
  File "/home/ubuntu/assignment3/env/lib/python3.5/site-packages/django/core/handlers/base.py", line 124, in _get_response
    response = wrapped_callback(request, *callback_args, **callback_kwargs)
  File "/home/ubuntu/assignment3/web-app-ci-cd-with-travis-ci-dong-alex/webresume/frontend/views.py", line 20, in image_file
    final = base64.b64decode(request).decode('utf-8')
  File "/usr/lib/python3.5/base64.py", line 81, in b64decode
    s = _bytes_from_decode_data(s)
  File "/usr/lib/python3.5/base64.py", line 46, in _bytes_from_decode_data
    "string, not %r" % s.__class__.__name__) from None
TypeError: argument should be a bytes-like object or ASCII string, not 'WSGIRequest'
[03/Oct/2018 20:48:57] "GET /image.jpg HTTP/1.1" 500 135025
Internal Server Error: /image.jpg
Traceback (most recent call last):
  File "/home/ubuntu/assignment3/env/lib/python3.5/site-packages/django/core/handlers/exception.py", line 34, in inner
    response = get_response(request)
  File "/home/ubuntu/assignment3/env/lib/python3.5/site-packages/django/core/handlers/base.py", line 126, in _get_response
    response = self.process_exception_by_middleware(e, request)
  File "/home/ubuntu/assignment3/env/lib/python3.5/site-packages/django/core/handlers/base.py", line 124, in _get_response
    response = wrapped_callback(request, *callback_args, **callback_kwargs)
  File "/home/ubuntu/assignment3/web-app-ci-cd-with-travis-ci-dong-alex/webresume/frontend/views.py", line 20, in image_file
    final = base64.b64decode(request).decode('utf-8')
  File "/usr/lib/python3.5/base64.py", line 81, in b64decode
    s = _bytes_from_decode_data(s)
  File "/usr/lib/python3.5/base64.py", line 46, in _bytes_from_decode_data
    "string, not %r" % s.__class__.__name__) from None
TypeError: argument should be a bytes-like object or ASCII string, not 'WSGIRequest'
[03/Oct/2018 20:48:57] "GET /image.jpg HTTP/1.1" 500 135025
Internal Server Error: /image.jpg
Traceback (most recent call last):
  File "/home/ubuntu/assignment3/env/lib/python3.5/site-packages/django/core/handlers/exception.py", line 34, in inner
    response = get_response(request)
  File "/home/ubuntu/assignment3/env/lib/python3.5/site-packages/django/core/handlers/base.py", line 126, in _get_response
    response = self.process_exception_by_middleware(e, request)
  File "/home/ubuntu/assignment3/env/lib/python3.5/site-packages/django/core/handlers/base.py", line 124, in _get_response
    response = wrapped_callback(request, *callback_args, **callback_kwargs)
  File "/home/ubuntu/assignment3/web-app-ci-cd-with-travis-ci-dong-alex/webresume/frontend/views.py", line 20, in image_file
    final = base64.b64decode(request).decode('utf-8')
  File "/usr/lib/python3.5/base64.py", line 81, in b64decode
    s = _bytes_from_decode_data(s)
  File "/usr/lib/python3.5/base64.py", line 46, in _bytes_from_decode_data
    "string, not %r" % s.__class__.__name__) from None
TypeError: argument should be a bytes-like object or ASCII string, not 'WSGIRequest'
[03/Oct/2018 20:48:57] "GET /image.jpg HTTP/1.1" 500 135025
Internal Server Error: /image.jpg
Traceback (most recent call last):
  File "/home/ubuntu/assignment3/env/lib/python3.5/site-packages/django/core/handlers/exception.py", line 34, in inner
    response = get_response(request)
  File "/home/ubuntu/assignment3/env/lib/python3.5/site-packages/django/core/handlers/base.py", line 126, in _get_response
    response = self.process_exception_by_middleware(e, request)
  File "/home/ubuntu/assignment3/env/lib/python3.5/site-packages/django/core/handlers/base.py", line 124, in _get_response
    response = wrapped_callback(request, *callback_args, **callback_kwargs)
  File "/home/ubuntu/assignment3/web-app-ci-cd-with-travis-ci-dong-alex/webresume/frontend/views.py", line 20, in image_file
    final = base64.b64decode(request).decode('utf-8')
  File "/usr/lib/python3.5/base64.py", line 81, in b64decode
    s = _bytes_from_decode_data(s)
  File "/usr/lib/python3.5/base64.py", line 46, in _bytes_from_decode_data
    "string, not %r" % s.__class__.__name__) from None
TypeError: argument should be a bytes-like object or ASCII string, not 'WSGIRequest'
[03/Oct/2018 20:48:57] "GET /image.jpg HTTP/1.1" 500 135025
Internal Server Error: /image.jpg
Traceback (most recent call last):
  File "/home/ubuntu/assignment3/env/lib/python3.5/site-packages/django/core/handlers/exception.py", line 34, in inner
    response = get_response(request)
  File "/home/ubuntu/assignment3/env/lib/python3.5/site-packages/django/core/handlers/base.py", line 126, in _get_response
    response = self.process_exception_by_middleware(e, request)
  File "/home/ubuntu/assignment3/env/lib/python3.5/site-packages/django/core/handlers/base.py", line 124, in _get_response
    response = wrapped_callback(request, *callback_args, **callback_kwargs)
  File "/home/ubuntu/assignment3/web-app-ci-cd-with-travis-ci-dong-alex/webresume/frontend/views.py", line 20, in image_file
    final = base64.b64decode(request).decode('utf-8')
  File "/usr/lib/python3.5/base64.py", line 81, in b64decode
    s = _bytes_from_decode_data(s)
  File "/usr/lib/python3.5/base64.py", line 46, in _bytes_from_decode_data
    "string, not %r" % s.__class__.__name__) from None
TypeError: argument should be a bytes-like object or ASCII string, not 'WSGIRequest'
[03/Oct/2018 20:48:58] "GET /image.jpg HTTP/1.1" 500 135025
Internal Server Error: /image.jpg
Traceback (most recent call last):
  File "/home/ubuntu/assignment3/env/lib/python3.5/site-packages/django/core/handlers/exception.py", line 34, in inner
    response = get_response(request)
  File "/home/ubuntu/assignment3/env/lib/python3.5/site-packages/django/core/handlers/base.py", line 126, in _get_response
    response = self.process_exception_by_middleware(e, request)
  File "/home/ubuntu/assignment3/env/lib/python3.5/site-packages/django/core/handlers/base.py", line 124, in _get_response
    response = wrapped_callback(request, *callback_args, **callback_kwargs)
  File "/home/ubuntu/assignment3/web-app-ci-cd-with-travis-ci-dong-alex/webresume/frontend/views.py", line 20, in image_file
    final = base64.b64decode(request).decode('utf-8')
  File "/usr/lib/python3.5/base64.py", line 81, in b64decode
    s = _bytes_from_decode_data(s)
  File "/usr/lib/python3.5/base64.py", line 46, in _bytes_from_decode_data
    "string, not %r" % s.__class__.__name__) from None
TypeError: argument should be a bytes-like object or ASCII string, not 'WSGIRequest'
[03/Oct/2018 20:48:59] "GET /image.jpg HTTP/1.1" 500 135025
Performing system checks...

System check identified no issues (0 silenced).
October 03, 2018 - 20:48:51
Django version 2.1.1, using settings 'webresume.settings'
Starting development server at http://0.0.0.0:8000/
Quit the server with CONTROL-C.
Internal Server Error: /image.jpg
Traceback (most recent call last):
  File "/home/ubuntu/assignment3/env/lib/python3.5/site-packages/django/core/handlers/exception.py", line 34, in inner
    response = get_response(request)
  File "/home/ubuntu/assignment3/env/lib/python3.5/site-packages/django/core/handlers/base.py", line 126, in _get_response
    response = self.process_exception_by_middleware(e, request)
  File "/home/ubuntu/assignment3/env/lib/python3.5/site-packages/django/core/handlers/base.py", line 124, in _get_response
    response = wrapped_callback(request, *callback_args, **callback_kwargs)
  File "/home/ubuntu/assignment3/web-app-ci-cd-with-travis-ci-dong-alex/webresume/frontend/views.py", line 20, in image_file
    final = base64.b64decode(request).decode('utf-8')
  File "/usr/lib/python3.5/base64.py", line 81, in b64decode
    s = _bytes_from_decode_data(s)
  File "/usr/lib/python3.5/base64.py", line 46, in _bytes_from_decode_data
    "string, not %r" % s.__class__.__name__) from None
TypeError: argument should be a bytes-like object or ASCII string, not 'WSGIRequest'
[03/Oct/2018 20:50:29] "GET /image.jpg HTTP/1.1" 500 135030
Internal Server Error: /image.jpg
Traceback (most recent call last):
  File "/home/ubuntu/assignment3/env/lib/python3.5/site-packages/django/core/handlers/exception.py", line 34, in inner
    response = get_response(request)
  File "/home/ubuntu/assignment3/env/lib/python3.5/site-packages/django/core/handlers/base.py", line 126, in _get_response
    response = self.process_exception_by_middleware(e, request)
  File "/home/ubuntu/assignment3/env/lib/python3.5/site-packages/django/core/handlers/base.py", line 124, in _get_response
    response = wrapped_callback(request, *callback_args, **callback_kwargs)
  File "/home/ubuntu/assignment3/web-app-ci-cd-with-travis-ci-dong-alex/webresume/frontend/views.py", line 20, in image_file
    final = base64.b64decode(request).decode('utf-8')
  File "/usr/lib/python3.5/base64.py", line 81, in b64decode
    s = _bytes_from_decode_data(s)
  File "/usr/lib/python3.5/base64.py", line 46, in _bytes_from_decode_data
    "string, not %r" % s.__class__.__name__) from None
TypeError: argument should be a bytes-like object or ASCII string, not 'WSGIRequest'
[03/Oct/2018 20:50:30] "GET /image.jpg HTTP/1.1" 500 135030
Internal Server Error: /image.jpg
Traceback (most recent call last):
  File "/home/ubuntu/assignment3/env/lib/python3.5/site-packages/django/core/handlers/exception.py", line 34, in inner
    response = get_response(request)
  File "/home/ubuntu/assignment3/env/lib/python3.5/site-packages/django/core/handlers/base.py", line 126, in _get_response
    response = self.process_exception_by_middleware(e, request)
  File "/home/ubuntu/assignment3/env/lib/python3.5/site-packages/django/core/handlers/base.py", line 124, in _get_response
    response = wrapped_callback(request, *callback_args, **callback_kwargs)
  File "/home/ubuntu/assignment3/web-app-ci-cd-with-travis-ci-dong-alex/webresume/frontend/views.py", line 20, in image_file
    final = base64.b64decode(request).decode('utf-8')
  File "/usr/lib/python3.5/base64.py", line 81, in b64decode
    s = _bytes_from_decode_data(s)
  File "/usr/lib/python3.5/base64.py", line 46, in _bytes_from_decode_data
    "string, not %r" % s.__class__.__name__) from None
TypeError: argument should be a bytes-like object or ASCII string, not 'WSGIRequest'
[03/Oct/2018 20:50:31] "GET /image.jpg HTTP/1.1" 500 135030
Internal Server Error: /image.jpg
Traceback (most recent call last):
  File "/home/ubuntu/assignment3/env/lib/python3.5/site-packages/django/core/handlers/exception.py", line 34, in inner
    response = get_response(request)
  File "/home/ubuntu/assignment3/env/lib/python3.5/site-packages/django/core/handlers/base.py", line 126, in _get_response
    response = self.process_exception_by_middleware(e, request)
  File "/home/ubuntu/assignment3/env/lib/python3.5/site-packages/django/core/handlers/base.py", line 124, in _get_response
    response = wrapped_callback(request, *callback_args, **callback_kwargs)
  File "/home/ubuntu/assignment3/web-app-ci-cd-with-travis-ci-dong-alex/webresume/frontend/views.py", line 20, in image_file
    final = base64.b64decode(request).decode('utf-8')
  File "/usr/lib/python3.5/base64.py", line 81, in b64decode
    s = _bytes_from_decode_data(s)
  File "/usr/lib/python3.5/base64.py", line 46, in _bytes_from_decode_data
    "string, not %r" % s.__class__.__name__) from None
TypeError: argument should be a bytes-like object or ASCII string, not 'WSGIRequest'
[03/Oct/2018 20:50:36] "GET /image.jpg HTTP/1.1" 500 135030
Performing system checks...

System check identified no issues (0 silenced).
October 03, 2018 - 20:50:25
Django version 2.1.1, using settings 'webresume.settings'
Starting development server at http://0.0.0.0:8000/
Quit the server with CONTROL-C.
Internal Server Error: /image.jpg
Traceback (most recent call last):
  File "/home/ubuntu/assignment3/env/lib/python3.5/site-packages/django/core/handlers/exception.py", line 34, in inner
    response = get_response(request)
  File "/home/ubuntu/assignment3/env/lib/python3.5/site-packages/django/core/handlers/base.py", line 126, in _get_response
    response = self.process_exception_by_middleware(e, request)
  File "/home/ubuntu/assignment3/env/lib/python3.5/site-packages/django/core/handlers/base.py", line 124, in _get_response
    response = wrapped_callback(request, *callback_args, **callback_kwargs)
  File "/home/ubuntu/assignment3/web-app-ci-cd-with-travis-ci-dong-alex/webresume/frontend/views.py", line 20, in image_file
    final = base64.b64decode(request).decode('utf-8')
  File "/usr/lib/python3.5/base64.py", line 81, in b64decode
    s = _bytes_from_decode_data(s)
  File "/usr/lib/python3.5/base64.py", line 46, in _bytes_from_decode_data
    "string, not %r" % s.__class__.__name__) from None
TypeError: argument should be a bytes-like object or ASCII string, not 'WSGIRequest'
[03/Oct/2018 20:52:04] "GET /image.jpg HTTP/1.1" 500 135163
Performing system checks...

System check identified no issues (0 silenced).
October 03, 2018 - 20:52:02
Django version 2.1.1, using settings 'webresume.settings'
Starting development server at http://0.0.0.0:8000/
Quit the server with CONTROL-C.
Internal Server Error: /image.jpg
Traceback (most recent call last):
  File "/home/ubuntu/assignment3/env/lib/python3.5/site-packages/django/core/handlers/exception.py", line 34, in inner
    response = get_response(request)
  File "/home/ubuntu/assignment3/env/lib/python3.5/site-packages/django/core/handlers/base.py", line 126, in _get_response
    response = self.process_exception_by_middleware(e, request)
  File "/home/ubuntu/assignment3/env/lib/python3.5/site-packages/django/core/handlers/base.py", line 124, in _get_response
    response = wrapped_callback(request, *callback_args, **callback_kwargs)
  File "/home/ubuntu/assignment3/web-app-ci-cd-with-travis-ci-dong-alex/webresume/frontend/views.py", line 20, in image_file
    final = base64.b64decode(request).decode('utf-8')
  File "/usr/lib/python3.5/base64.py", line 81, in b64decode
    s = _bytes_from_decode_data(s)
  File "/usr/lib/python3.5/base64.py", line 46, in _bytes_from_decode_data
    "string, not %r" % s.__class__.__name__) from None
TypeError: argument should be a bytes-like object or ASCII string, not 'WSGIRequest'
[03/Oct/2018 20:53:01] "GET /image.jpg HTTP/1.1" 500 135290
Internal Server Error: /image.jpg
Traceback (most recent call last):
  File "/home/ubuntu/assignment3/env/lib/python3.5/site-packages/django/core/handlers/exception.py", line 34, in inner
    response = get_response(request)
  File "/home/ubuntu/assignment3/env/lib/python3.5/site-packages/django/core/handlers/base.py", line 126, in _get_response
    response = self.process_exception_by_middleware(e, request)
  File "/home/ubuntu/assignment3/env/lib/python3.5/site-packages/django/core/handlers/base.py", line 124, in _get_response
    response = wrapped_callback(request, *callback_args, **callback_kwargs)
  File "/home/ubuntu/assignment3/web-app-ci-cd-with-travis-ci-dong-alex/webresume/frontend/views.py", line 20, in image_file
    final = base64.b64decode(request).decode('utf-8')
  File "/usr/lib/python3.5/base64.py", line 81, in b64decode
    s = _bytes_from_decode_data(s)
  File "/usr/lib/python3.5/base64.py", line 46, in _bytes_from_decode_data
    "string, not %r" % s.__class__.__name__) from None
TypeError: argument should be a bytes-like object or ASCII string, not 'WSGIRequest'
[03/Oct/2018 20:53:02] "GET /image.jpg HTTP/1.1" 500 135290
Internal Server Error: /image.jpg
Traceback (most recent call last):
  File "/home/ubuntu/assignment3/env/lib/python3.5/site-packages/django/core/handlers/exception.py", line 34, in inner
    response = get_response(request)
  File "/home/ubuntu/assignment3/env/lib/python3.5/site-packages/django/core/handlers/base.py", line 126, in _get_response
    response = self.process_exception_by_middleware(e, request)
  File "/home/ubuntu/assignment3/env/lib/python3.5/site-packages/django/core/handlers/base.py", line 124, in _get_response
    response = wrapped_callback(request, *callback_args, **callback_kwargs)
  File "/home/ubuntu/assignment3/web-app-ci-cd-with-travis-ci-dong-alex/webresume/frontend/views.py", line 20, in image_file
    final = base64.b64decode(request).decode('utf-8')
  File "/usr/lib/python3.5/base64.py", line 81, in b64decode
    s = _bytes_from_decode_data(s)
  File "/usr/lib/python3.5/base64.py", line 46, in _bytes_from_decode_data
    "string, not %r" % s.__class__.__name__) from None
TypeError: argument should be a bytes-like object or ASCII string, not 'WSGIRequest'
[03/Oct/2018 20:53:03] "GET /image.jpg HTTP/1.1" 500 135290
Internal Server Error: /image.jpg
Traceback (most recent call last):
  File "/home/ubuntu/assignment3/env/lib/python3.5/site-packages/django/core/handlers/exception.py", line 34, in inner
    response = get_response(request)
  File "/home/ubuntu/assignment3/env/lib/python3.5/site-packages/django/core/handlers/base.py", line 126, in _get_response
    response = self.process_exception_by_middleware(e, request)
  File "/home/ubuntu/assignment3/env/lib/python3.5/site-packages/django/core/handlers/base.py", line 124, in _get_response
    response = wrapped_callback(request, *callback_args, **callback_kwargs)
  File "/home/ubuntu/assignment3/web-app-ci-cd-with-travis-ci-dong-alex/webresume/frontend/views.py", line 20, in image_file
    final = base64.b64decode(request).decode('utf-8')
  File "/usr/lib/python3.5/base64.py", line 81, in b64decode
    s = _bytes_from_decode_data(s)
  File "/usr/lib/python3.5/base64.py", line 46, in _bytes_from_decode_data
    "string, not %r" % s.__class__.__name__) from None
TypeError: argument should be a bytes-like object or ASCII string, not 'WSGIRequest'
[03/Oct/2018 20:53:05] "GET /image.jpg HTTP/1.1" 500 135290
Performing system checks...

System check identified no issues (0 silenced).
October 03, 2018 - 20:53:00
Django version 2.1.1, using settings 'webresume.settings'
Starting development server at http://0.0.0.0:8000/
Quit the server with CONTROL-C.
[03/Oct/2018 20:54:00] "GET /image.jpg HTTP/1.1" 200 0
Performing system checks...

System check identified no issues (0 silenced).
October 03, 2018 - 20:53:59
Django version 2.1.1, using settings 'webresume.settings'
Starting development server at http://0.0.0.0:8000/
Quit the server with CONTROL-C.
[03/Oct/2018 20:55:42] "GET /image.jpg HTTP/1.1" 200 0
Performing system checks...

System check identified no issues (0 silenced).
October 03, 2018 - 20:55:35
Django version 2.1.1, using settings 'webresume.settings'
Starting development server at http://0.0.0.0:8000/
Quit the server with CONTROL-C.
Performing system checks...

System check identified no issues (0 silenced).
October 03, 2018 - 20:56:45
Django version 2.1.1, using settings 'webresume.settings'
Starting development server at http://0.0.0.0:8000/
Quit the server with CONTROL-C.
[03/Oct/2018 21:00:34] "GET /image.jpg HTTP/1.1" 200 44969
[03/Oct/2018 21:00:37] "GET /image.jpg HTTP/1.1" 200 44969
Performing system checks...

System check identified no issues (0 silenced).
October 03, 2018 - 21:00:31
Django version 2.1.1, using settings 'webresume.settings'
Starting development server at http://0.0.0.0:8000/
Quit the server with CONTROL-C.
[03/Oct/2018 21:09:48] "GET / HTTP/1.1" 200 1137
Performing system checks...

System check identified no issues (0 silenced).
October 03, 2018 - 21:09:46
Django version 2.1.1, using settings 'webresume.settings'
Starting development server at http://0.0.0.0:8000/
Quit the server with CONTROL-C.
Unhandled exception in thread started by <function check_errors.<locals>.wrapper at 0x7fc078570840>
Traceback (most recent call last):
  File "/home/ubuntu/assignment3/env/lib/python3.5/site-packages/django/utils/autoreload.py", line 225, in wrapper
    fn(*args, **kwargs)
  File "/home/ubuntu/assignment3/env/lib/python3.5/site-packages/django/core/management/commands/runserver.py", line 109, in inner_run
    autoreload.raise_last_exception()
  File "/home/ubuntu/assignment3/env/lib/python3.5/site-packages/django/utils/autoreload.py", line 248, in raise_last_exception
    raise _exception[1]
  File "/home/ubuntu/assignment3/env/lib/python3.5/site-packages/django/core/management/__init__.py", line 337, in execute
    autoreload.check_errors(django.setup)()
  File "/home/ubuntu/assignment3/env/lib/python3.5/site-packages/django/utils/autoreload.py", line 225, in wrapper
    fn(*args, **kwargs)
  File "/home/ubuntu/assignment3/env/lib/python3.5/site-packages/django/__init__.py", line 24, in setup
    apps.populate(settings.INSTALLED_APPS)
  File "/home/ubuntu/assignment3/env/lib/python3.5/site-packages/django/apps/registry.py", line 120, in populate
    app_config.ready()
  File "/home/ubuntu/assignment3/env/lib/python3.5/site-packages/django/contrib/admin/apps.py", line 24, in ready
    self.module.autodiscover()
  File "/home/ubuntu/assignment3/env/lib/python3.5/site-packages/django/contrib/admin/__init__.py", line 26, in autodiscover
    autodiscover_modules('admin', register_to=site)
  File "/home/ubuntu/assignment3/env/lib/python3.5/site-packages/django/utils/module_loading.py", line 47, in autodiscover_modules
    import_module('%s.%s' % (app_config.name, module_to_search))
  File "/usr/lib/python3.5/importlib/__init__.py", line 126, in import_module
    return _bootstrap._gcd_import(name[level:], package, level)
  File "<frozen importlib._bootstrap>", line 986, in _gcd_import
  File "<frozen importlib._bootstrap>", line 969, in _find_and_load
  File "<frozen importlib._bootstrap>", line 958, in _find_and_load_unlocked
  File "<frozen importlib._bootstrap>", line 673, in _load_unlocked
  File "<frozen importlib._bootstrap_external>", line 665, in exec_module
  File "<frozen importlib._bootstrap>", line 222, in _call_with_frames_removed
  File "/home/ubuntu/assignment3/web-app-ci-cd-with-travis-ci-dong-alex/webresume/api/admin.py", line 4, in <module>
    dmin.site.register(Person)
NameError: name 'dmin' is not defined
[03/Oct/2018 21:10:22] "GET / HTTP/1.1" 200 1137
[03/Oct/2018 21:10:50] "GET / HTTP/1.1" 200 1137
[03/Oct/2018 21:10:50] "GET /api/ HTTP/1.1" 200 5284
[03/Oct/2018 21:11:04] "GET /api/ HTTP/1.1" 200 5284
[03/Oct/2018 21:11:05] "GET /api/person/1 HTTP/1.1" 301 0
Not Found: /api/person/1/
[03/Oct/2018 21:11:05] "GET /api/person/1/ HTTP/1.1" 404 7675
[03/Oct/2018 21:11:06] "GET /static/rest_framework/fonts/glyphicons-halflings-regular.woff2 HTTP/1.1" 200 18028
Not Found: /api/person/1/
[03/Oct/2018 21:14:35] "GET /api/person/1/ HTTP/1.1" 404 7675
Not Found: /api/person/1/
[03/Oct/2018 21:14:39] "GET /api/person/1/ HTTP/1.1" 404 7675
[03/Oct/2018 21:14:45] "GET /api/ HTTP/1.1" 200 5284
Not Found: /api/person/1/
[03/Oct/2018 21:14:49] "GET /api/person/1/ HTTP/1.1" 404 7675
[03/Oct/2018 21:14:50] "GET /api/ HTTP/1.1" 200 5284
Not Found: /api/Person/1
[03/Oct/2018 21:14:51] "GET /api/Person/1 HTTP/1.1" 404 3927
Not Found: /api/person/1/
[03/Oct/2018 21:14:56] "GET /api/person/1/ HTTP/1.1" 404 7675
Not Found: /api/person/1/
[03/Oct/2018 21:14:56] "GET /api/person/1/ HTTP/1.1" 404 7675
Performing system checks...

System check identified no issues (0 silenced).
October 03, 2018 - 21:10:22
Django version 2.1.1, using settings 'webresume.settings'
Starting development server at http://0.0.0.0:8000/
Quit the server with CONTROL-C.
Unhandled exception in thread started by <function check_errors.<locals>.wrapper at 0x7fa49ac119d8>
Traceback (most recent call last):
  File "/home/ubuntu/assignment3/env/lib/python3.5/site-packages/django/utils/autoreload.py", line 225, in wrapper
    fn(*args, **kwargs)
  File "/home/ubuntu/assignment3/env/lib/python3.5/site-packages/django/core/management/commands/runserver.py", line 109, in inner_run
    autoreload.raise_last_exception()
  File "/home/ubuntu/assignment3/env/lib/python3.5/site-packages/django/utils/autoreload.py", line 248, in raise_last_exception
    raise _exception[1]
  File "/home/ubuntu/assignment3/env/lib/python3.5/site-packages/django/core/management/__init__.py", line 337, in execute
    autoreload.check_errors(django.setup)()
  File "/home/ubuntu/assignment3/env/lib/python3.5/site-packages/django/utils/autoreload.py", line 225, in wrapper
    fn(*args, **kwargs)
  File "/home/ubuntu/assignment3/env/lib/python3.5/site-packages/django/__init__.py", line 24, in setup
    apps.populate(settings.INSTALLED_APPS)
  File "/home/ubuntu/assignment3/env/lib/python3.5/site-packages/django/apps/registry.py", line 120, in populate
    app_config.ready()
  File "/home/ubuntu/assignment3/env/lib/python3.5/site-packages/django/contrib/admin/apps.py", line 24, in ready
    self.module.autodiscover()
  File "/home/ubuntu/assignment3/env/lib/python3.5/site-packages/django/contrib/admin/__init__.py", line 26, in autodiscover
    autodiscover_modules('admin', register_to=site)
  File "/home/ubuntu/assignment3/env/lib/python3.5/site-packages/django/utils/module_loading.py", line 47, in autodiscover_modules
    import_module('%s.%s' % (app_config.name, module_to_search))
  File "/usr/lib/python3.5/importlib/__init__.py", line 126, in import_module
    return _bootstrap._gcd_import(name[level:], package, level)
  File "<frozen importlib._bootstrap>", line 986, in _gcd_import
  File "<frozen importlib._bootstrap>", line 969, in _find_and_load
  File "<frozen importlib._bootstrap>", line 958, in _find_and_load_unlocked
  File "<frozen importlib._bootstrap>", line 673, in _load_unlocked
  File "<frozen importlib._bootstrap_external>", line 665, in exec_module
  File "<frozen importlib._bootstrap>", line 222, in _call_with_frames_removed
  File "/home/ubuntu/assignment3/web-app-ci-cd-with-travis-ci-dong-alex/webresume/api/admin.py", line 4, in <module>
    admin.site.resiter(Person)
  File "/home/ubuntu/assignment3/env/lib/python3.5/site-packages/django/utils/functional.py", line 214, in inner
    return func(self._wrapped, *args)
AttributeError: 'AdminSite' object has no attribute 'resiter'
Unhandled exception in thread started by <function check_errors.<locals>.wrapper at 0x7f9b53bdea60>
Traceback (most recent call last):
  File "/home/ubuntu/assignment3/env/lib/python3.5/site-packages/django/utils/autoreload.py", line 225, in wrapper
    fn(*args, **kwargs)
  File "/home/ubuntu/assignment3/env/lib/python3.5/site-packages/django/core/management/commands/runserver.py", line 109, in inner_run
    autoreload.raise_last_exception()
  File "/home/ubuntu/assignment3/env/lib/python3.5/site-packages/django/utils/autoreload.py", line 248, in raise_last_exception
    raise _exception[1]
  File "/home/ubuntu/assignment3/env/lib/python3.5/site-packages/django/core/management/__init__.py", line 337, in execute
    autoreload.check_errors(django.setup)()
  File "/home/ubuntu/assignment3/env/lib/python3.5/site-packages/django/utils/autoreload.py", line 225, in wrapper
    fn(*args, **kwargs)
  File "/home/ubuntu/assignment3/env/lib/python3.5/site-packages/django/__init__.py", line 24, in setup
    apps.populate(settings.INSTALLED_APPS)
  File "/home/ubuntu/assignment3/env/lib/python3.5/site-packages/django/apps/registry.py", line 120, in populate
    app_config.ready()
  File "/home/ubuntu/assignment3/env/lib/python3.5/site-packages/django/contrib/admin/apps.py", line 24, in ready
    self.module.autodiscover()
  File "/home/ubuntu/assignment3/env/lib/python3.5/site-packages/django/contrib/admin/__init__.py", line 26, in autodiscover
    autodiscover_modules('admin', register_to=site)
  File "/home/ubuntu/assignment3/env/lib/python3.5/site-packages/django/utils/module_loading.py", line 47, in autodiscover_modules
    import_module('%s.%s' % (app_config.name, module_to_search))
  File "/usr/lib/python3.5/importlib/__init__.py", line 126, in import_module
    return _bootstrap._gcd_import(name[level:], package, level)
  File "<frozen importlib._bootstrap>", line 986, in _gcd_import
  File "<frozen importlib._bootstrap>", line 969, in _find_and_load
  File "<frozen importlib._bootstrap>", line 958, in _find_and_load_unlocked
  File "<frozen importlib._bootstrap>", line 673, in _load_unlocked
  File "<frozen importlib._bootstrap_external>", line 665, in exec_module
  File "<frozen importlib._bootstrap>", line 222, in _call_with_frames_removed
  File "/home/ubuntu/assignment3/web-app-ci-cd-with-travis-ci-dong-alex/webresume/api/admin.py", line 4, in <module>
    admin.site.resiter(Person)
  File "/home/ubuntu/assignment3/env/lib/python3.5/site-packages/django/utils/functional.py", line 214, in inner
    return func(self._wrapped, *args)
AttributeError: 'AdminSite' object has no attribute 'resiter'
Performing system checks...

System check identified no issues (0 silenced).
October 03, 2018 - 21:17:09
Django version 2.1.1, using settings 'webresume.settings'
Starting development server at http://0.0.0.0:8000/
Quit the server with CONTROL-C.
Not Found: /api/person/1/
[03/Oct/2018 21:20:32] "GET /api/person/1/ HTTP/1.1" 404 7675
Performing system checks...

System check identified no issues (0 silenced).
October 03, 2018 - 21:20:06
Django version 2.1.1, using settings 'webresume.settings'
Starting development server at http://0.0.0.0:8000/
Quit the server with CONTROL-C.
Performing system checks...

System check identified no issues (0 silenced).
October 03, 2018 - 21:21:59
Django version 2.1.1, using settings 'webresume.settings'
Starting development server at http://0.0.0.0:8000/
Quit the server with CONTROL-C.
Performing system checks...

System check identified no issues (0 silenced).
October 03, 2018 - 21:29:30
Django version 2.1.1, using settings 'webresume.settings'
Starting development server at http://0.0.0.0:8000/
Quit the server with CONTROL-C.
Performing system checks...

System check identified no issues (0 silenced).
October 03, 2018 - 21:29:38
Django version 2.1.1, using settings 'webresume.settings'
Starting development server at http://0.0.0.0:8000/
Quit the server with CONTROL-C.
Performing system checks...

System check identified no issues (0 silenced).
October 03, 2018 - 21:30:06
Django version 2.1.1, using settings 'webresume.settings'
Starting development server at http://0.0.0.0:8000/
Quit the server with CONTROL-C.
Performing system checks...

System check identified no issues (0 silenced).
October 03, 2018 - 21:36:38
Django version 2.1.1, using settings 'webresume.settings'
Starting development server at http://0.0.0.0:8000/
Quit the server with CONTROL-C.
Performing system checks...

System check identified no issues (0 silenced).
October 03, 2018 - 21:37:11
Django version 2.1.1, using settings 'webresume.settings'
Starting development server at http://0.0.0.0:8000/
Quit the server with CONTROL-C.
Not Found: /api/person/1/
[03/Oct/2018 21:40:39] "GET /api/person/1/ HTTP/1.1" 404 7675
[03/Oct/2018 21:40:41] "GET / HTTP/1.1" 200 1248
[03/Oct/2018 21:40:41] "GET / HTTP/1.1" 200 1248
Performing system checks...

System check identified no issues (0 silenced).
October 03, 2018 - 21:38:11
Django version 2.1.1, using settings 'webresume.settings'
Starting development server at http://0.0.0.0:8000/
Quit the server with CONTROL-C.
Unhandled exception in thread started by <function check_errors.<locals>.wrapper at 0x7f1ab57f4840>
Traceback (most recent call last):
  File "/home/ubuntu/assignment3/env/lib/python3.5/site-packages/django/utils/autoreload.py", line 225, in wrapper
    fn(*args, **kwargs)
  File "/home/ubuntu/assignment3/env/lib/python3.5/site-packages/django/core/management/commands/runserver.py", line 109, in inner_run
    autoreload.raise_last_exception()
  File "/home/ubuntu/assignment3/env/lib/python3.5/site-packages/django/utils/autoreload.py", line 248, in raise_last_exception
    raise _exception[1]
  File "/home/ubuntu/assignment3/env/lib/python3.5/site-packages/django/core/management/__init__.py", line 337, in execute
    autoreload.check_errors(django.setup)()
  File "/home/ubuntu/assignment3/env/lib/python3.5/site-packages/django/utils/autoreload.py", line 225, in wrapper
    fn(*args, **kwargs)
  File "/home/ubuntu/assignment3/env/lib/python3.5/site-packages/django/__init__.py", line 24, in setup
    apps.populate(settings.INSTALLED_APPS)
  File "/home/ubuntu/assignment3/env/lib/python3.5/site-packages/django/apps/registry.py", line 120, in populate
    app_config.ready()
  File "/home/ubuntu/assignment3/env/lib/python3.5/site-packages/django/contrib/admin/apps.py", line 24, in ready
    self.module.autodiscover()
  File "/home/ubuntu/assignment3/env/lib/python3.5/site-packages/django/contrib/admin/__init__.py", line 26, in autodiscover
    autodiscover_modules('admin', register_to=site)
  File "/home/ubuntu/assignment3/env/lib/python3.5/site-packages/django/utils/module_loading.py", line 47, in autodiscover_modules
    import_module('%s.%s' % (app_config.name, module_to_search))
  File "/usr/lib/python3.5/importlib/__init__.py", line 126, in import_module
    return _bootstrap._gcd_import(name[level:], package, level)
  File "<frozen importlib._bootstrap>", line 986, in _gcd_import
  File "<frozen importlib._bootstrap>", line 969, in _find_and_load
  File "<frozen importlib._bootstrap>", line 958, in _find_and_load_unlocked
  File "<frozen importlib._bootstrap>", line 673, in _load_unlocked
  File "<frozen importlib._bootstrap_external>", line 665, in exec_module
  File "<frozen importlib._bootstrap>", line 222, in _call_with_frames_removed
  File "/home/ubuntu/assignment3/web-app-ci-cd-with-travis-ci-dong-alex/webresume/api/admin.py", line 2, in <module>
    from models import Person
ImportError: No module named 'models'
[03/Oct/2018 21:42:30] "GET / HTTP/1.1" 200 1248
[03/Oct/2018 21:42:52] "GET /admin HTTP/1.1" 301 0
[03/Oct/2018 21:42:52] "GET /admin/ HTTP/1.1" 302 0
[03/Oct/2018 21:42:52] "GET /admin/login/?next=/admin/ HTTP/1.1" 200 1819
[03/Oct/2018 21:42:52] "GET /static/admin/css/base.css HTTP/1.1" 200 16225
[03/Oct/2018 21:42:52] "GET /static/admin/css/login.css HTTP/1.1" 200 1203
[03/Oct/2018 21:42:52] "GET /static/admin/css/responsive.css HTTP/1.1" 200 17976
[03/Oct/2018 21:42:52] "GET /static/admin/css/fonts.css HTTP/1.1" 200 423
[03/Oct/2018 21:42:52] "GET /static/admin/fonts/Roboto-Light-webfont.woff HTTP/1.1" 200 81348
[03/Oct/2018 21:42:52] "GET /static/admin/fonts/Roboto-Regular-webfont.woff HTTP/1.1" 200 80304
[03/Oct/2018 21:43:03] "POST /admin/login/?next=/admin/ HTTP/1.1" 200 1981
[03/Oct/2018 21:43:03] "GET /static/admin/fonts/Roboto-Bold-webfont.woff HTTP/1.1" 200 82564
[03/Oct/2018 21:46:18] "GET / HTTP/1.1" 200 1248
[03/Oct/2018 21:46:19] "GET /api/ HTTP/1.1" 200 5284
Not Found: /api/person/1/
[03/Oct/2018 21:46:19] "GET /api/person/1/ HTTP/1.1" 404 7675
Not Found: /api/person/1/
[03/Oct/2018 21:46:20] "GET /api/person/1/ HTTP/1.1" 404 7675
Not Found: /api/person/1/
[03/Oct/2018 21:46:24] "GET /api/person/1/ HTTP/1.1" 404 7675
Bad Request: /api/person/1/
[03/Oct/2018 21:46:27] "GET /api/person/1/?format=api HTTP/1.1" 400 7915
Bad Request: /api/person/1/
[03/Oct/2018 21:46:34] "GET /api/person/1/?format=vnd.api%2Bjson HTTP/1.1" 400 101
Bad Request: /api/person/1/
[03/Oct/2018 21:48:09] "GET /api/person/1/?format=api HTTP/1.1" 400 7915
Bad Request: /api/person/1/
[03/Oct/2018 21:48:13] "GET /api/person/1/?format=api HTTP/1.1" 400 7915
Bad Request: /api/person/1/
[03/Oct/2018 21:48:14] "GET /api/person/1/?format=vnd.api%2Bjson HTTP/1.1" 400 101
Not Found: /api/person/1/
[03/Oct/2018 21:48:15] "GET /api/person/1/ HTTP/1.1" 404 7675
/home/ubuntu/assignment3/env/lib/python3.5/site-packages/rest_framework/pagination.py:198: UnorderedObjectListWarning: Pagination may yield inconsistent results with an unordered object_list: <class 'api.models.Person'> QuerySet.
  paginator = self.django_paginator_class(queryset, page_size)
[03/Oct/2018 21:48:36] "GET /api/person/ HTTP/1.1" 200 7889
[03/Oct/2018 21:48:45] "GET /api/ HTTP/1.1" 200 5284
[03/Oct/2018 21:48:56] "OPTIONS /api/ HTTP/1.1" 200 5741
[03/Oct/2018 21:49:01] "OPTIONS /api/ HTTP/1.1" 200 5741
[03/Oct/2018 21:51:24] "GET /api/ HTTP/1.1" 200 5284
Not Found: /api/person/1/
[03/Oct/2018 21:51:31] "GET /api/person/1/ HTTP/1.1" 404 7675
Not Found: /api/person/1/
[03/Oct/2018 21:51:32] "GET /api/person/1/ HTTP/1.1" 404 7675
Performing system checks...

System check identified no issues (0 silenced).
October 03, 2018 - 21:42:16
Django version 2.1.1, using settings 'webresume.settings'
Starting development server at http://0.0.0.0:8000/
Quit the server with CONTROL-C.
Performing system checks...

System check identified no issues (0 silenced).
October 03, 2018 - 21:58:17
Django version 2.1.1, using settings 'webresume.settings'
Starting development server at http://0.0.0.0:8000/
Quit the server with CONTROL-C.
Not Found: /api/person/1/
[03/Oct/2018 22:01:01] "GET /api/person/1/ HTTP/1.1" 404 7675
[03/Oct/2018 22:01:02] "GET /api/ HTTP/1.1" 200 5284
[03/Oct/2018 22:01:02] "GET / HTTP/1.1" 200 1253
Not Found: /api/person/1/
[03/Oct/2018 22:01:02] "GET /api/person/1/ HTTP/1.1" 404 98
Performing system checks...

System check identified no issues (0 silenced).
October 03, 2018 - 21:59:09
Django version 2.1.1, using settings 'webresume.settings'
Starting development server at http://0.0.0.0:8000/
Quit the server with CONTROL-C.
Unhandled exception in thread started by <function check_errors.<locals>.wrapper at 0x7f82133136a8>
Traceback (most recent call last):
  File "/home/ubuntu/assignment3/env/lib/python3.5/site-packages/django/utils/autoreload.py", line 225, in wrapper
    fn(*args, **kwargs)
  File "/home/ubuntu/assignment3/env/lib/python3.5/site-packages/django/core/management/commands/runserver.py", line 117, in inner_run
    self.check(display_num_errors=True)
  File "/home/ubuntu/assignment3/env/lib/python3.5/site-packages/django/core/management/base.py", line 379, in check
    include_deployment_checks=include_deployment_checks,
  File "/home/ubuntu/assignment3/env/lib/python3.5/site-packages/django/core/management/base.py", line 366, in _run_checks
    return checks.run_checks(**kwargs)
  File "/home/ubuntu/assignment3/env/lib/python3.5/site-packages/django/core/checks/registry.py", line 71, in run_checks
    new_errors = check(app_configs=app_configs)
  File "/home/ubuntu/assignment3/env/lib/python3.5/site-packages/django/core/checks/urls.py", line 40, in check_url_namespaces_unique
    all_namespaces = _load_all_namespaces(resolver)
  File "/home/ubuntu/assignment3/env/lib/python3.5/site-packages/django/core/checks/urls.py", line 57, in _load_all_namespaces
    url_patterns = getattr(resolver, 'url_patterns', [])
  File "/home/ubuntu/assignment3/env/lib/python3.5/site-packages/django/utils/functional.py", line 37, in __get__
    res = instance.__dict__[self.name] = self.func(instance)
  File "/home/ubuntu/assignment3/env/lib/python3.5/site-packages/django/urls/resolvers.py", line 533, in url_patterns
    patterns = getattr(self.urlconf_module, "urlpatterns", self.urlconf_module)
  File "/home/ubuntu/assignment3/env/lib/python3.5/site-packages/django/utils/functional.py", line 37, in __get__
    res = instance.__dict__[self.name] = self.func(instance)
  File "/home/ubuntu/assignment3/env/lib/python3.5/site-packages/django/urls/resolvers.py", line 526, in urlconf_module
    return import_module(self.urlconf_name)
  File "/usr/lib/python3.5/importlib/__init__.py", line 126, in import_module
    return _bootstrap._gcd_import(name[level:], package, level)
  File "<frozen importlib._bootstrap>", line 986, in _gcd_import
  File "<frozen importlib._bootstrap>", line 969, in _find_and_load
  File "<frozen importlib._bootstrap>", line 958, in _find_and_load_unlocked
  File "<frozen importlib._bootstrap>", line 673, in _load_unlocked
  File "<frozen importlib._bootstrap_external>", line 665, in exec_module
  File "<frozen importlib._bootstrap>", line 222, in _call_with_frames_removed
  File "/home/ubuntu/assignment3/web-app-ci-cd-with-travis-ci-dong-alex/webresume/webresume/urls.py", line 22, in <module>
    path('', include('frontend.urls')),
  File "/home/ubuntu/assignment3/env/lib/python3.5/site-packages/django/urls/conf.py", line 34, in include
    urlconf_module = import_module(urlconf_module)
  File "/usr/lib/python3.5/importlib/__init__.py", line 126, in import_module
    return _bootstrap._gcd_import(name[level:], package, level)
  File "<frozen importlib._bootstrap>", line 986, in _gcd_import
  File "<frozen importlib._bootstrap>", line 969, in _find_and_load
  File "<frozen importlib._bootstrap>", line 958, in _find_and_load_unlocked
  File "<frozen importlib._bootstrap>", line 673, in _load_unlocked
  File "<frozen importlib._bootstrap_external>", line 665, in exec_module
  File "<frozen importlib._bootstrap>", line 222, in _call_with_frames_removed
  File "/home/ubuntu/assignment3/web-app-ci-cd-with-travis-ci-dong-alex/webresume/frontend/urls.py", line 2, in <module>
    from . import views
  File "/home/ubuntu/assignment3/web-app-ci-cd-with-travis-ci-dong-alex/webresume/frontend/views.py", line 15
    def index(request):
      ^
SyntaxError: invalid syntax
Performing system checks...

Performing system checks...

System check identified no issues (0 silenced).
October 03, 2018 - 22:03:21
Django version 2.1.1, using settings 'webresume.settings'
Starting development server at http://0.0.0.0:8000/
Quit the server with CONTROL-C.
Unhandled exception in thread started by <function check_errors.<locals>.wrapper at 0x7ff5b82516a8>
Traceback (most recent call last):
  File "/home/ubuntu/assignment3/env/lib/python3.5/site-packages/django/utils/autoreload.py", line 225, in wrapper
    fn(*args, **kwargs)
  File "/home/ubuntu/assignment3/env/lib/python3.5/site-packages/django/core/management/commands/runserver.py", line 117, in inner_run
    self.check(display_num_errors=True)
  File "/home/ubuntu/assignment3/env/lib/python3.5/site-packages/django/core/management/base.py", line 379, in check
    include_deployment_checks=include_deployment_checks,
  File "/home/ubuntu/assignment3/env/lib/python3.5/site-packages/django/core/management/base.py", line 366, in _run_checks
    return checks.run_checks(**kwargs)
  File "/home/ubuntu/assignment3/env/lib/python3.5/site-packages/django/core/checks/registry.py", line 71, in run_checks
    new_errors = check(app_configs=app_configs)
  File "/home/ubuntu/assignment3/env/lib/python3.5/site-packages/django/core/checks/urls.py", line 13, in check_url_config
    return check_resolver(resolver)
  File "/home/ubuntu/assignment3/env/lib/python3.5/site-packages/django/core/checks/urls.py", line 23, in check_resolver
    return check_method()
  File "/home/ubuntu/assignment3/env/lib/python3.5/site-packages/django/urls/resolvers.py", line 396, in check
    for pattern in self.url_patterns:
  File "/home/ubuntu/assignment3/env/lib/python3.5/site-packages/django/utils/functional.py", line 37, in __get__
    res = instance.__dict__[self.name] = self.func(instance)
  File "/home/ubuntu/assignment3/env/lib/python3.5/site-packages/django/urls/resolvers.py", line 533, in url_patterns
    patterns = getattr(self.urlconf_module, "urlpatterns", self.urlconf_module)
  File "/home/ubuntu/assignment3/env/lib/python3.5/site-packages/django/utils/functional.py", line 37, in __get__
    res = instance.__dict__[self.name] = self.func(instance)
  File "/home/ubuntu/assignment3/env/lib/python3.5/site-packages/django/urls/resolvers.py", line 526, in urlconf_module
    return import_module(self.urlconf_name)
  File "/usr/lib/python3.5/importlib/__init__.py", line 126, in import_module
    return _bootstrap._gcd_import(name[level:], package, level)
  File "<frozen importlib._bootstrap>", line 986, in _gcd_import
  File "<frozen importlib._bootstrap>", line 969, in _find_and_load
  File "<frozen importlib._bootstrap>", line 958, in _find_and_load_unlocked
  File "<frozen importlib._bootstrap>", line 673, in _load_unlocked
  File "<frozen importlib._bootstrap_external>", line 665, in exec_module
  File "<frozen importlib._bootstrap>", line 222, in _call_with_frames_removed
  File "/home/ubuntu/assignment3/web-app-ci-cd-with-travis-ci-dong-alex/webresume/webresume/urls.py", line 22, in <module>
    path('', include('frontend.urls')),
  File "/home/ubuntu/assignment3/env/lib/python3.5/site-packages/django/urls/conf.py", line 34, in include
    urlconf_module = import_module(urlconf_module)
  File "/usr/lib/python3.5/importlib/__init__.py", line 126, in import_module
    return _bootstrap._gcd_import(name[level:], package, level)
  File "<frozen importlib._bootstrap>", line 986, in _gcd_import
  File "<frozen importlib._bootstrap>", line 969, in _find_and_load
  File "<frozen importlib._bootstrap>", line 958, in _find_and_load_unlocked
  File "<frozen importlib._bootstrap>", line 673, in _load_unlocked
  File "<frozen importlib._bootstrap_external>", line 665, in exec_module
  File "<frozen importlib._bootstrap>", line 222, in _call_with_frames_removed
  File "/home/ubuntu/assignment3/web-app-ci-cd-with-travis-ci-dong-alex/webresume/frontend/urls.py", line 8, in <module>
    path('person', views.PersonInstance),
AttributeError: module 'frontend.views' has no attribute 'PersonInstance'
Performing system checks...

Unhandled exception in thread started by <function check_errors.<locals>.wrapper at 0x7faeb76b26a8>
Traceback (most recent call last):
  File "/home/ubuntu/assignment3/env/lib/python3.5/site-packages/django/utils/autoreload.py", line 225, in wrapper
    fn(*args, **kwargs)
  File "/home/ubuntu/assignment3/env/lib/python3.5/site-packages/django/core/management/commands/runserver.py", line 117, in inner_run
    self.check(display_num_errors=True)
  File "/home/ubuntu/assignment3/env/lib/python3.5/site-packages/django/core/management/base.py", line 379, in check
    include_deployment_checks=include_deployment_checks,
  File "/home/ubuntu/assignment3/env/lib/python3.5/site-packages/django/core/management/base.py", line 366, in _run_checks
    return checks.run_checks(**kwargs)
  File "/home/ubuntu/assignment3/env/lib/python3.5/site-packages/django/core/checks/registry.py", line 71, in run_checks
    new_errors = check(app_configs=app_configs)
  File "/home/ubuntu/assignment3/env/lib/python3.5/site-packages/django/core/checks/urls.py", line 13, in check_url_config
    return check_resolver(resolver)
  File "/home/ubuntu/assignment3/env/lib/python3.5/site-packages/django/core/checks/urls.py", line 23, in check_resolver
    return check_method()
  File "/home/ubuntu/assignment3/env/lib/python3.5/site-packages/django/urls/resolvers.py", line 396, in check
    for pattern in self.url_patterns:
  File "/home/ubuntu/assignment3/env/lib/python3.5/site-packages/django/utils/functional.py", line 37, in __get__
    res = instance.__dict__[self.name] = self.func(instance)
  File "/home/ubuntu/assignment3/env/lib/python3.5/site-packages/django/urls/resolvers.py", line 533, in url_patterns
    patterns = getattr(self.urlconf_module, "urlpatterns", self.urlconf_module)
  File "/home/ubuntu/assignment3/env/lib/python3.5/site-packages/django/utils/functional.py", line 37, in __get__
    res = instance.__dict__[self.name] = self.func(instance)
  File "/home/ubuntu/assignment3/env/lib/python3.5/site-packages/django/urls/resolvers.py", line 526, in urlconf_module
    return import_module(self.urlconf_name)
  File "/usr/lib/python3.5/importlib/__init__.py", line 126, in import_module
    return _bootstrap._gcd_import(name[level:], package, level)
  File "<frozen importlib._bootstrap>", line 986, in _gcd_import
  File "<frozen importlib._bootstrap>", line 969, in _find_and_load
  File "<frozen importlib._bootstrap>", line 958, in _find_and_load_unlocked
  File "<frozen importlib._bootstrap>", line 673, in _load_unlocked
  File "<frozen importlib._bootstrap_external>", line 665, in exec_module
  File "<frozen importlib._bootstrap>", line 222, in _call_with_frames_removed
  File "/home/ubuntu/assignment3/web-app-ci-cd-with-travis-ci-dong-alex/webresume/webresume/urls.py", line 22, in <module>
    path('', include('frontend.urls')),
  File "/home/ubuntu/assignment3/env/lib/python3.5/site-packages/django/urls/conf.py", line 34, in include
    urlconf_module = import_module(urlconf_module)
  File "/usr/lib/python3.5/importlib/__init__.py", line 126, in import_module
    return _bootstrap._gcd_import(name[level:], package, level)
  File "<frozen importlib._bootstrap>", line 986, in _gcd_import
  File "<frozen importlib._bootstrap>", line 969, in _find_and_load
  File "<frozen importlib._bootstrap>", line 958, in _find_and_load_unlocked
  File "<frozen importlib._bootstrap>", line 673, in _load_unlocked
  File "<frozen importlib._bootstrap_external>", line 665, in exec_module
  File "<frozen importlib._bootstrap>", line 222, in _call_with_frames_removed
  File "/home/ubuntu/assignment3/web-app-ci-cd-with-travis-ci-dong-alex/webresume/frontend/urls.py", line 8, in <module>
    path('person', views.PersonInstance),
AttributeError: module 'frontend.views' has no attribute 'PersonInstance'
Performing system checks...

Performing system checks...

System check identified no issues (0 silenced).
October 03, 2018 - 22:04:06
Django version 2.1.1, using settings 'webresume.settings'
Starting development server at http://0.0.0.0:8000/
Quit the server with CONTROL-C.
[03/Oct/2018 22:05:17] "GET / HTTP/1.1" 200 1253
Not Found: /api/person/1/
[03/Oct/2018 22:05:17] "GET /api/person/1/ HTTP/1.1" 404 98
[03/Oct/2018 22:05:17] "GET / HTTP/1.1" 200 1253
Not Found: /api/person/1/
[03/Oct/2018 22:05:17] "GET /api/person/1/ HTTP/1.1" 404 98
[03/Oct/2018 22:05:19] "GET /api/ HTTP/1.1" 200 5284
Not Found: /api/person/1/
[03/Oct/2018 22:05:20] "GET /api/person/1/ HTTP/1.1" 404 7675
/home/ubuntu/assignment3/env/lib/python3.5/site-packages/rest_framework/pagination.py:198: UnorderedObjectListWarning: Pagination may yield inconsistent results with an unordered object_list: <class 'api.models.Person'> QuerySet.
  paginator = self.django_paginator_class(queryset, page_size)
[03/Oct/2018 22:05:22] "GET /api/person/ HTTP/1.1" 200 7889
[03/Oct/2018 22:05:22] "GET /api/person/ HTTP/1.1" 200 7889
Not Found: /api/person/1/
[03/Oct/2018 22:05:27] "GET /api/person/1/ HTTP/1.1" 404 7675
Not Found: /api/person/1/
[03/Oct/2018 22:05:57] "GET /api/person/1/ HTTP/1.1" 404 7675
Not Found: /api/person/1/
[03/Oct/2018 22:06:43] "GET /api/person/1/ HTTP/1.1" 404 7675
Not Found: /api/person/1/
[03/Oct/2018 22:06:45] "GET /api/person/1/ HTTP/1.1" 404 7675
Not Found: /api/person/1/
[03/Oct/2018 22:06:45] "GET /api/person/1/ HTTP/1.1" 404 7675
[03/Oct/2018 22:06:46] "GET / HTTP/1.1" 200 1253
Not Found: /api/person/1/
[03/Oct/2018 22:06:46] "GET /api/person/1/ HTTP/1.1" 404 98
[03/Oct/2018 22:06:46] "GET / HTTP/1.1" 200 1253
Not Found: /api/person/1/
[03/Oct/2018 22:06:46] "GET /api/person/1/ HTTP/1.1" 404 98
Performing system checks...

System check identified no issues (0 silenced).
October 03, 2018 - 22:05:10
Django version 2.1.1, using settings 'webresume.settings'
Starting development server at http://0.0.0.0:8000/
Quit the server with CONTROL-C.
Performing system checks...

System check identified no issues (0 silenced).
October 03, 2018 - 22:07:42
Django version 2.1.1, using settings 'webresume.settings'
Starting development server at http://0.0.0.0:8000/
Quit the server with CONTROL-C.
Performing system checks...

System check identified no issues (0 silenced).
October 03, 2018 - 22:07:46
Django version 2.1.1, using settings 'webresume.settings'
Starting development server at http://0.0.0.0:8000/
Quit the server with CONTROL-C.
Performing system checks...

System check identified no issues (0 silenced).
October 03, 2018 - 22:07:51
Django version 2.1.1, using settings 'webresume.settings'
Starting development server at http://0.0.0.0:8000/
Quit the server with CONTROL-C.
Unhandled exception in thread started by <function check_errors.<locals>.wrapper at 0x7feaaf14d6a8>
Traceback (most recent call last):
  File "/home/ubuntu/assignment3/env/lib/python3.5/site-packages/django/utils/autoreload.py", line 225, in wrapper
    fn(*args, **kwargs)
  File "/home/ubuntu/assignment3/env/lib/python3.5/site-packages/django/core/management/commands/runserver.py", line 117, in inner_run
    self.check(display_num_errors=True)
  File "/home/ubuntu/assignment3/env/lib/python3.5/site-packages/django/core/management/base.py", line 379, in check
    include_deployment_checks=include_deployment_checks,
  File "/home/ubuntu/assignment3/env/lib/python3.5/site-packages/django/core/management/base.py", line 366, in _run_checks
    return checks.run_checks(**kwargs)
  File "/home/ubuntu/assignment3/env/lib/python3.5/site-packages/django/core/checks/registry.py", line 71, in run_checks
    new_errors = check(app_configs=app_configs)
  File "/home/ubuntu/assignment3/env/lib/python3.5/site-packages/django/core/checks/urls.py", line 13, in check_url_config
    return check_resolver(resolver)
  File "/home/ubuntu/assignment3/env/lib/python3.5/site-packages/django/core/checks/urls.py", line 23, in check_resolver
    return check_method()
  File "/home/ubuntu/assignment3/env/lib/python3.5/site-packages/django/urls/resolvers.py", line 396, in check
    for pattern in self.url_patterns:
  File "/home/ubuntu/assignment3/env/lib/python3.5/site-packages/django/utils/functional.py", line 37, in __get__
    res = instance.__dict__[self.name] = self.func(instance)
  File "/home/ubuntu/assignment3/env/lib/python3.5/site-packages/django/urls/resolvers.py", line 533, in url_patterns
    patterns = getattr(self.urlconf_module, "urlpatterns", self.urlconf_module)
  File "/home/ubuntu/assignment3/env/lib/python3.5/site-packages/django/utils/functional.py", line 37, in __get__
    res = instance.__dict__[self.name] = self.func(instance)
  File "/home/ubuntu/assignment3/env/lib/python3.5/site-packages/django/urls/resolvers.py", line 526, in urlconf_module
    return import_module(self.urlconf_name)
  File "/usr/lib/python3.5/importlib/__init__.py", line 126, in import_module
    return _bootstrap._gcd_import(name[level:], package, level)
  File "<frozen importlib._bootstrap>", line 986, in _gcd_import
  File "<frozen importlib._bootstrap>", line 969, in _find_and_load
  File "<frozen importlib._bootstrap>", line 958, in _find_and_load_unlocked
  File "<frozen importlib._bootstrap>", line 673, in _load_unlocked
  File "<frozen importlib._bootstrap_external>", line 665, in exec_module
  File "<frozen importlib._bootstrap>", line 222, in _call_with_frames_removed
  File "/home/ubuntu/assignment3/web-app-ci-cd-with-travis-ci-dong-alex/webresume/webresume/urls.py", line 22, in <module>
    path('', include('frontend.urls')),
  File "/home/ubuntu/assignment3/env/lib/python3.5/site-packages/django/urls/conf.py", line 34, in include
    urlconf_module = import_module(urlconf_module)
  File "/usr/lib/python3.5/importlib/__init__.py", line 126, in import_module
    return _bootstrap._gcd_import(name[level:], package, level)
  File "<frozen importlib._bootstrap>", line 986, in _gcd_import
  File "<frozen importlib._bootstrap>", line 969, in _find_and_load
  File "<frozen importlib._bootstrap>", line 958, in _find_and_load_unlocked
  File "<frozen importlib._bootstrap>", line 673, in _load_unlocked
  File "<frozen importlib._bootstrap_external>", line 665, in exec_module
  File "<frozen importlib._bootstrap>", line 222, in _call_with_frames_removed
  File "/home/ubuntu/assignment3/web-app-ci-cd-with-travis-ci-dong-alex/webresume/frontend/urls.py", line 8, in <module>
    path('person', views.PersonData),
AttributeError: module 'frontend.views' has no attribute 'PersonData'
Performing system checks...

Unhandled exception in thread started by <function check_errors.<locals>.wrapper at 0x7f4d935256a8>
Traceback (most recent call last):
  File "/home/ubuntu/assignment3/env/lib/python3.5/site-packages/django/utils/autoreload.py", line 225, in wrapper
    fn(*args, **kwargs)
  File "/home/ubuntu/assignment3/env/lib/python3.5/site-packages/django/core/management/commands/runserver.py", line 117, in inner_run
    self.check(display_num_errors=True)
  File "/home/ubuntu/assignment3/env/lib/python3.5/site-packages/django/core/management/base.py", line 379, in check
    include_deployment_checks=include_deployment_checks,
  File "/home/ubuntu/assignment3/env/lib/python3.5/site-packages/django/core/management/base.py", line 366, in _run_checks
    return checks.run_checks(**kwargs)
  File "/home/ubuntu/assignment3/env/lib/python3.5/site-packages/django/core/checks/registry.py", line 71, in run_checks
    new_errors = check(app_configs=app_configs)
  File "/home/ubuntu/assignment3/env/lib/python3.5/site-packages/django/core/checks/urls.py", line 13, in check_url_config
    return check_resolver(resolver)
  File "/home/ubuntu/assignment3/env/lib/python3.5/site-packages/django/core/checks/urls.py", line 23, in check_resolver
    return check_method()
  File "/home/ubuntu/assignment3/env/lib/python3.5/site-packages/django/urls/resolvers.py", line 396, in check
    for pattern in self.url_patterns:
  File "/home/ubuntu/assignment3/env/lib/python3.5/site-packages/django/utils/functional.py", line 37, in __get__
    res = instance.__dict__[self.name] = self.func(instance)
  File "/home/ubuntu/assignment3/env/lib/python3.5/site-packages/django/urls/resolvers.py", line 533, in url_patterns
    patterns = getattr(self.urlconf_module, "urlpatterns", self.urlconf_module)
  File "/home/ubuntu/assignment3/env/lib/python3.5/site-packages/django/utils/functional.py", line 37, in __get__
    res = instance.__dict__[self.name] = self.func(instance)
  File "/home/ubuntu/assignment3/env/lib/python3.5/site-packages/django/urls/resolvers.py", line 526, in urlconf_module
    return import_module(self.urlconf_name)
  File "/usr/lib/python3.5/importlib/__init__.py", line 126, in import_module
    return _bootstrap._gcd_import(name[level:], package, level)
  File "<frozen importlib._bootstrap>", line 986, in _gcd_import
  File "<frozen importlib._bootstrap>", line 969, in _find_and_load
  File "<frozen importlib._bootstrap>", line 958, in _find_and_load_unlocked
  File "<frozen importlib._bootstrap>", line 673, in _load_unlocked
  File "<frozen importlib._bootstrap_external>", line 665, in exec_module
  File "<frozen importlib._bootstrap>", line 222, in _call_with_frames_removed
  File "/home/ubuntu/assignment3/web-app-ci-cd-with-travis-ci-dong-alex/webresume/webresume/urls.py", line 22, in <module>
    path('', include('frontend.urls')),
  File "/home/ubuntu/assignment3/env/lib/python3.5/site-packages/django/urls/conf.py", line 34, in include
    urlconf_module = import_module(urlconf_module)
  File "/usr/lib/python3.5/importlib/__init__.py", line 126, in import_module
    return _bootstrap._gcd_import(name[level:], package, level)
  File "<frozen importlib._bootstrap>", line 986, in _gcd_import
  File "<frozen importlib._bootstrap>", line 969, in _find_and_load
  File "<frozen importlib._bootstrap>", line 958, in _find_and_load_unlocked
  File "<frozen importlib._bootstrap>", line 673, in _load_unlocked
  File "<frozen importlib._bootstrap_external>", line 665, in exec_module
  File "<frozen importlib._bootstrap>", line 222, in _call_with_frames_removed
  File "/home/ubuntu/assignment3/web-app-ci-cd-with-travis-ci-dong-alex/webresume/frontend/urls.py", line 8, in <module>
    path('person', views.PersonData),
AttributeError: module 'frontend.views' has no attribute 'PersonData'
Performing system checks...

Unhandled exception in thread started by <function check_errors.<locals>.wrapper at 0x7fe2e87f26a8>
Traceback (most recent call last):
  File "/home/ubuntu/assignment3/env/lib/python3.5/site-packages/django/utils/autoreload.py", line 225, in wrapper
    fn(*args, **kwargs)
  File "/home/ubuntu/assignment3/env/lib/python3.5/site-packages/django/core/management/commands/runserver.py", line 117, in inner_run
    self.check(display_num_errors=True)
  File "/home/ubuntu/assignment3/env/lib/python3.5/site-packages/django/core/management/base.py", line 379, in check
    include_deployment_checks=include_deployment_checks,
  File "/home/ubuntu/assignment3/env/lib/python3.5/site-packages/django/core/management/base.py", line 366, in _run_checks
    return checks.run_checks(**kwargs)
  File "/home/ubuntu/assignment3/env/lib/python3.5/site-packages/django/core/checks/registry.py", line 71, in run_checks
    new_errors = check(app_configs=app_configs)
  File "/home/ubuntu/assignment3/env/lib/python3.5/site-packages/django/core/checks/urls.py", line 13, in check_url_config
    return check_resolver(resolver)
  File "/home/ubuntu/assignment3/env/lib/python3.5/site-packages/django/core/checks/urls.py", line 23, in check_resolver
    return check_method()
  File "/home/ubuntu/assignment3/env/lib/python3.5/site-packages/django/urls/resolvers.py", line 396, in check
    for pattern in self.url_patterns:
  File "/home/ubuntu/assignment3/env/lib/python3.5/site-packages/django/utils/functional.py", line 37, in __get__
    res = instance.__dict__[self.name] = self.func(instance)
  File "/home/ubuntu/assignment3/env/lib/python3.5/site-packages/django/urls/resolvers.py", line 533, in url_patterns
    patterns = getattr(self.urlconf_module, "urlpatterns", self.urlconf_module)
  File "/home/ubuntu/assignment3/env/lib/python3.5/site-packages/django/utils/functional.py", line 37, in __get__
    res = instance.__dict__[self.name] = self.func(instance)
  File "/home/ubuntu/assignment3/env/lib/python3.5/site-packages/django/urls/resolvers.py", line 526, in urlconf_module
    return import_module(self.urlconf_name)
  File "/usr/lib/python3.5/importlib/__init__.py", line 126, in import_module
    return _bootstrap._gcd_import(name[level:], package, level)
  File "<frozen importlib._bootstrap>", line 986, in _gcd_import
  File "<frozen importlib._bootstrap>", line 969, in _find_and_load
  File "<frozen importlib._bootstrap>", line 958, in _find_and_load_unlocked
  File "<frozen importlib._bootstrap>", line 673, in _load_unlocked
  File "<frozen importlib._bootstrap_external>", line 665, in exec_module
  File "<frozen importlib._bootstrap>", line 222, in _call_with_frames_removed
  File "/home/ubuntu/assignment3/web-app-ci-cd-with-travis-ci-dong-alex/webresume/webresume/urls.py", line 22, in <module>
    path('', include('frontend.urls')),
  File "/home/ubuntu/assignment3/env/lib/python3.5/site-packages/django/urls/conf.py", line 34, in include
    urlconf_module = import_module(urlconf_module)
  File "/usr/lib/python3.5/importlib/__init__.py", line 126, in import_module
    return _bootstrap._gcd_import(name[level:], package, level)
  File "<frozen importlib._bootstrap>", line 986, in _gcd_import
  File "<frozen importlib._bootstrap>", line 969, in _find_and_load
  File "<frozen importlib._bootstrap>", line 958, in _find_and_load_unlocked
  File "<frozen importlib._bootstrap>", line 673, in _load_unlocked
  File "<frozen importlib._bootstrap_external>", line 665, in exec_module
  File "<frozen importlib._bootstrap>", line 222, in _call_with_frames_removed
  File "/home/ubuntu/assignment3/web-app-ci-cd-with-travis-ci-dong-alex/webresume/frontend/urls.py", line 8, in <module>
    path('person', views.PersonData),
AttributeError: module 'frontend.views' has no attribute 'PersonData'
Performing system checks...

[03/Oct/2018 23:02:57] "GET / HTTP/1.1" 200 1253
Not Found: /api/person/1/
[03/Oct/2018 23:02:57] "GET /api/person/1/ HTTP/1.1" 404 98
[03/Oct/2018 23:02:59] "GET / HTTP/1.1" 200 1253
Not Found: /api/person/1/
[03/Oct/2018 23:02:59] "GET /api/person/1/ HTTP/1.1" 404 98
[03/Oct/2018 23:03:00] "GET /admin/ HTTP/1.1" 302 0
[03/Oct/2018 23:03:00] "GET /admin/login/?next=/admin/ HTTP/1.1" 200 1819
[03/Oct/2018 23:03:04] "POST /admin/login/?next=/admin/ HTTP/1.1" 302 0
[03/Oct/2018 23:03:04] "GET /admin/ HTTP/1.1" 200 3696
[03/Oct/2018 23:03:04] "GET /static/admin/css/dashboard.css HTTP/1.1" 200 412
[03/Oct/2018 23:03:04] "GET /static/admin/img/icon-addlink.svg HTTP/1.1" 200 331
[03/Oct/2018 23:03:04] "GET /static/admin/img/icon-changelink.svg HTTP/1.1" 200 380
[03/Oct/2018 23:03:08] "GET /admin/api/person/ HTTP/1.1" 200 3157
[03/Oct/2018 23:03:08] "GET /static/admin/css/changelists.css HTTP/1.1" 200 6170
[03/Oct/2018 23:03:08] "GET /admin/jsi18n/ HTTP/1.1" 200 3185
[03/Oct/2018 23:03:08] "GET /static/admin/js/jquery.init.js HTTP/1.1" 200 363
[03/Oct/2018 23:03:08] "GET /static/admin/js/core.js HTTP/1.1" 200 7134
[03/Oct/2018 23:03:08] "GET /static/admin/js/admin/RelatedObjectLookups.js HTTP/1.1" 200 6918
[03/Oct/2018 23:03:08] "GET /static/admin/js/urlify.js HTTP/1.1" 200 8972
[03/Oct/2018 23:03:08] "GET /static/admin/js/actions.js HTTP/1.1" 200 6538
[03/Oct/2018 23:03:08] "GET /static/admin/js/prepopulate.js HTTP/1.1" 200 1530
[03/Oct/2018 23:03:08] "GET /static/admin/js/vendor/jquery/jquery.js HTTP/1.1" 200 271751
[03/Oct/2018 23:03:08] "GET /static/admin/js/vendor/xregexp/xregexp.js HTTP/1.1" 200 128820
[03/Oct/2018 23:03:08] "GET /static/admin/img/tooltag-add.svg HTTP/1.1" 200 331
[03/Oct/2018 23:03:10] "GET /admin/api/person/add/ HTTP/1.1" 200 6439
[03/Oct/2018 23:03:10] "GET /static/admin/css/forms.css HTTP/1.1" 200 8505
[03/Oct/2018 23:03:10] "GET /admin/jsi18n/ HTTP/1.1" 200 3185
[03/Oct/2018 23:03:10] "GET /static/admin/js/change_form.js HTTP/1.1" 200 712
[03/Oct/2018 23:03:10] "GET /static/admin/js/prepopulate_init.js HTTP/1.1" 200 495
[03/Oct/2018 23:03:10] "GET /static/admin/css/widgets.css HTTP/1.1" 200 10340
[03/Oct/2018 23:03:39] "POST /admin/api/person/add/ HTTP/1.1" 302 0
[03/Oct/2018 23:03:39] "GET /admin/api/person/ HTTP/1.1" 200 4514
[03/Oct/2018 23:03:39] "GET /admin/jsi18n/ HTTP/1.1" 200 3185
[03/Oct/2018 23:03:39] "GET /static/admin/img/icon-yes.svg HTTP/1.1" 200 436
[03/Oct/2018 23:03:41] "GET /admin/api/person/1/change/ HTTP/1.1" 200 6707
[03/Oct/2018 23:03:41] "GET /admin/jsi18n/ HTTP/1.1" 200 3185
[03/Oct/2018 23:03:52] "GET /admin/api/person/1/change/ HTTP/1.1" 200 6707
[03/Oct/2018 23:03:52] "GET /admin/jsi18n/ HTTP/1.1" 200 3185
[03/Oct/2018 23:03:54] "GET /admin/api/person/ HTTP/1.1" 200 4326
[03/Oct/2018 23:03:54] "GET / HTTP/1.1" 200 1253
[03/Oct/2018 23:03:54] "GET /api/person/1/ HTTP/1.1" 200 164
[03/Oct/2018 23:03:55] "GET /api/ HTTP/1.1" 200 5317
[03/Oct/2018 23:03:56] "GET /api/person/1/ HTTP/1.1" 200 5609
/home/ubuntu/assignment3/env/lib/python3.5/site-packages/rest_framework/pagination.py:198: UnorderedObjectListWarning: Pagination may yield inconsistent results with an unordered object_list: <class 'api.models.Person'> QuerySet.
  paginator = self.django_paginator_class(queryset, page_size)
[03/Oct/2018 23:03:56] "GET /api/person/ HTTP/1.1" 200 8433
[03/Oct/2018 23:04:02] "GET /api/person/ HTTP/1.1" 200 8433
[03/Oct/2018 23:04:03] "GET /api/person/1/ HTTP/1.1" 200 5609
[03/Oct/2018 23:04:03] "GET /api/person/1/ HTTP/1.1" 200 5609
[03/Oct/2018 23:04:04] "GET / HTTP/1.1" 200 1253
[03/Oct/2018 23:04:04] "GET /api/person/1/ HTTP/1.1" 200 164
[03/Oct/2018 23:04:04] "GET / HTTP/1.1" 200 1253
[03/Oct/2018 23:04:04] "GET /api/person/1/ HTTP/1.1" 200 164
Not Found: /status
[04/Oct/2018 00:27:19] "GET /status HTTP/1.1" 404 2534
[04/Oct/2018 04:44:35] "GET / HTTP/1.1" 200 1655
Not Found: /css/materialize.min.css
[04/Oct/2018 04:44:35] "GET /css/materialize.min.css HTTP/1.1" 404 2585
[04/Oct/2018 04:44:35] "GET /api/person/1/ HTTP/1.1" 200 164
[04/Oct/2018 04:44:37] "GET / HTTP/1.1" 200 1655
Not Found: /css/materialize.min.css
[04/Oct/2018 04:44:37] "GET /css/materialize.min.css HTTP/1.1" 404 2585
[04/Oct/2018 04:44:37] "GET /api/person/1/ HTTP/1.1" 200 164
[04/Oct/2018 04:44:38] "GET / HTTP/1.1" 200 1655
Not Found: /css/materialize.min.css
[04/Oct/2018 04:44:38] "GET /css/materialize.min.css HTTP/1.1" 404 2585
Not Found: /css/materialize.min.css
[04/Oct/2018 04:44:38] "GET /css/materialize.min.css HTTP/1.1" 404 2585
[04/Oct/2018 04:44:39] "GET /api/person/1/ HTTP/1.1" 200 164
[04/Oct/2018 04:44:39] "GET /api/person/1/ HTTP/1.1" 200 164
[04/Oct/2018 04:44:54] "GET / HTTP/1.1" 200 1655
[04/Oct/2018 04:44:54] "GET /api/person/1/ HTTP/1.1" 200 164
Not Found: /css/materialize.min.css
[04/Oct/2018 04:44:54] "GET /css/materialize.min.css HTTP/1.1" 404 2585
[04/Oct/2018 04:44:55] "GET /api/person/1/ HTTP/1.1" 200 164
Not Found: /css/materialize.min.css
[04/Oct/2018 04:44:57] "GET /css/materialize.min.css HTTP/1.1" 404 2585
[04/Oct/2018 04:46:34] "GET / HTTP/1.1" 200 1800
Not Found: /css/materialize.min.css
[04/Oct/2018 04:46:34] "GET /css/materialize.min.css HTTP/1.1" 404 2585
[04/Oct/2018 04:46:34] "GET /api/person/1/ HTTP/1.1" 200 164
[04/Oct/2018 04:47:10] "GET / HTTP/1.1" 200 1813
Not Found: /css/materialize.min.css
[04/Oct/2018 04:47:10] "GET /css/materialize.min.css HTTP/1.1" 404 2585
[04/Oct/2018 04:47:10] "GET /api/person/1/ HTTP/1.1" 200 164
[04/Oct/2018 04:47:11] "GET /api/person/1/ HTTP/1.1" 200 164
[04/Oct/2018 04:57:55] "GET / HTTP/1.1" 200 2090
[04/Oct/2018 04:57:56] "GET /api/person/1/ HTTP/1.1" 200 164
[04/Oct/2018 05:28:37] "GET / HTTP/1.1" 200 2280
[04/Oct/2018 05:28:37] "GET /api/person/1/ HTTP/1.1" 200 164
[04/Oct/2018 05:29:24] "GET / HTTP/1.1" 200 2285
[04/Oct/2018 05:29:24] "GET /api/person/1/ HTTP/1.1" 200 164
[04/Oct/2018 05:29:24] "GET /api/person/1/ HTTP/1.1" 200 164
[04/Oct/2018 05:32:23] "GET / HTTP/1.1" 200 2071
[04/Oct/2018 05:32:23] "GET /api/person/1/ HTTP/1.1" 200 164
[04/Oct/2018 05:32:24] "GET /api/person/1/ HTTP/1.1" 200 164
[04/Oct/2018 05:32:46] "GET / HTTP/1.1" 200 2026
[04/Oct/2018 05:32:46] "GET /api/person/1/ HTTP/1.1" 200 164
[04/Oct/2018 05:32:46] "GET /api/person/1/ HTTP/1.1" 200 164
[04/Oct/2018 05:33:06] "GET /api/person/1/ HTTP/1.1" 200 164
[04/Oct/2018 05:33:06] "GET / HTTP/1.1" 200 2048
[04/Oct/2018 05:33:06] "GET /api/person/1/ HTTP/1.1" 200 164
[04/Oct/2018 05:33:30] "GET / HTTP/1.1" 200 2043
[04/Oct/2018 05:33:30] "GET /api/person/1/ HTTP/1.1" 200 164
[04/Oct/2018 05:33:30] "GET /api/person/1/ HTTP/1.1" 200 164
[04/Oct/2018 05:33:45] "GET /api/person/1/ HTTP/1.1" 200 164
[04/Oct/2018 05:33:45] "GET / HTTP/1.1" 200 2005
[04/Oct/2018 05:33:45] "GET /api/person/1/ HTTP/1.1" 200 164
[04/Oct/2018 05:36:29] "GET / HTTP/1.1" 200 2015
[04/Oct/2018 05:36:29] "GET /api/person/1/ HTTP/1.1" 200 164
[04/Oct/2018 05:36:30] "GET /api/person/1/ HTTP/1.1" 200 164
[04/Oct/2018 05:36:45] "GET / HTTP/1.1" 200 2015
[04/Oct/2018 05:36:45] "GET /api/person/1/ HTTP/1.1" 200 164
[04/Oct/2018 05:36:45] "GET /api/person/1/ HTTP/1.1" 200 164
[04/Oct/2018 05:37:39] "GET /api/person/1/ HTTP/1.1" 200 164
[04/Oct/2018 05:37:39] "GET / HTTP/1.1" 200 2028
[04/Oct/2018 05:37:39] "GET /api/person/1/ HTTP/1.1" 200 164
[04/Oct/2018 05:37:52] "GET / HTTP/1.1" 200 2026
[04/Oct/2018 05:37:52] "GET /api/person/1/ HTTP/1.1" 200 164
[04/Oct/2018 05:37:53] "GET /api/person/1/ HTTP/1.1" 200 164
[04/Oct/2018 05:38:32] "GET /api/person/1/ HTTP/1.1" 200 164
[04/Oct/2018 05:38:32] "GET / HTTP/1.1" 200 2036
[04/Oct/2018 05:38:33] "GET /api/person/1/ HTTP/1.1" 200 164
[04/Oct/2018 05:40:15] "GET / HTTP/1.1" 200 2047
[04/Oct/2018 05:40:15] "GET /api/person/1/ HTTP/1.1" 200 164
[04/Oct/2018 05:40:15] "GET /api/person/1/ HTTP/1.1" 200 164
[04/Oct/2018 05:42:02] "GET / HTTP/1.1" 200 2124
[04/Oct/2018 05:42:02] "GET /api/person/1/ HTTP/1.1" 200 164
[04/Oct/2018 05:42:03] "GET /api/person/1/ HTTP/1.1" 200 164
[04/Oct/2018 05:43:42] "GET /api/person/1/ HTTP/1.1" 200 164
[04/Oct/2018 05:43:43] "GET / HTTP/1.1" 200 2144
[04/Oct/2018 05:43:43] "GET /api/person/1/ HTTP/1.1" 200 164
[04/Oct/2018 05:46:22] "GET / HTTP/1.1" 200 2153
[04/Oct/2018 05:46:22] "GET /api/person/1/ HTTP/1.1" 200 164
[04/Oct/2018 05:46:23] "GET /api/person/1/ HTTP/1.1" 200 164
[04/Oct/2018 05:46:58] "GET / HTTP/1.1" 200 2159
[04/Oct/2018 05:46:58] "GET /api/person/1/ HTTP/1.1" 200 164
[04/Oct/2018 05:47:00] "GET /api/person/1/ HTTP/1.1" 200 164
[04/Oct/2018 05:47:24] "GET / HTTP/1.1" 200 2159
[04/Oct/2018 05:47:24] "GET /api/person/1/ HTTP/1.1" 200 164
[04/Oct/2018 05:47:25] "GET /api/person/1/ HTTP/1.1" 200 164
[04/Oct/2018 05:52:08] "GET / HTTP/1.1" 200 2161
[04/Oct/2018 05:52:08] "GET /api/person/1/ HTTP/1.1" 200 164
[04/Oct/2018 05:52:09] "GET /api/person/1/ HTTP/1.1" 200 164
[04/Oct/2018 05:53:48] "GET / HTTP/1.1" 200 2191
[04/Oct/2018 05:53:48] "GET /api/person/1/ HTTP/1.1" 200 164
[04/Oct/2018 05:53:48] "GET /api/person/1/ HTTP/1.1" 200 164
[04/Oct/2018 05:54:13] "GET /api/person/1/ HTTP/1.1" 200 164
[04/Oct/2018 05:54:14] "GET / HTTP/1.1" 200 2191
[04/Oct/2018 05:54:14] "GET /api/person/1/ HTTP/1.1" 200 164
[04/Oct/2018 05:54:56] "GET / HTTP/1.1" 200 2190
[04/Oct/2018 05:54:56] "GET /api/person/1/ HTTP/1.1" 200 164
[04/Oct/2018 05:54:56] "GET /api/person/1/ HTTP/1.1" 200 164
[04/Oct/2018 05:55:04] "GET / HTTP/1.1" 200 2191
[04/Oct/2018 05:55:05] "GET /api/person/1/ HTTP/1.1" 200 164
[04/Oct/2018 05:55:05] "GET /api/person/1/ HTTP/1.1" 200 164
[04/Oct/2018 05:55:13] "GET / HTTP/1.1" 200 2192
[04/Oct/2018 05:55:13] "GET /api/person/1/ HTTP/1.1" 200 164
[04/Oct/2018 05:55:14] "GET /api/person/1/ HTTP/1.1" 200 164
[04/Oct/2018 05:56:33] "GET / HTTP/1.1" 200 2412
[04/Oct/2018 05:56:33] "GET /api/person/1/ HTTP/1.1" 200 164
[04/Oct/2018 05:56:34] "GET /api/person/1/ HTTP/1.1" 200 164
[04/Oct/2018 05:57:41] "GET / HTTP/1.1" 200 2723
[04/Oct/2018 05:57:41] "GET /api/person/1/ HTTP/1.1" 200 164
[04/Oct/2018 05:57:41] "GET /api/person/1/ HTTP/1.1" 200 164
[04/Oct/2018 05:58:54] "GET / HTTP/1.1" 200 2831
[04/Oct/2018 05:58:54] "GET /api/person/1/ HTTP/1.1" 200 164
[04/Oct/2018 05:58:54] "GET /api/person/1/ HTTP/1.1" 200 164
[04/Oct/2018 05:59:31] "GET /api/person/1/ HTTP/1.1" 200 164
[04/Oct/2018 05:59:31] "GET / HTTP/1.1" 200 2831
[04/Oct/2018 05:59:31] "GET /api/person/1/ HTTP/1.1" 200 164
[04/Oct/2018 06:00:14] "GET /api/person/1/ HTTP/1.1" 200 164
[04/Oct/2018 06:00:15] "GET / HTTP/1.1" 200 2846
[04/Oct/2018 06:00:15] "GET /api/person/1/ HTTP/1.1" 200 164
[04/Oct/2018 06:01:40] "GET / HTTP/1.1" 200 2859
[04/Oct/2018 06:01:40] "GET /api/person/1/ HTTP/1.1" 200 164
[04/Oct/2018 06:01:41] "GET /api/person/1/ HTTP/1.1" 200 164
[04/Oct/2018 06:02:30] "GET / HTTP/1.1" 200 2864
[04/Oct/2018 06:02:30] "GET /api/person/1/ HTTP/1.1" 200 164
[04/Oct/2018 06:02:31] "GET /api/person/1/ HTTP/1.1" 200 164
[04/Oct/2018 06:02:54] "GET / HTTP/1.1" 200 2864
[04/Oct/2018 06:02:54] "GET /api/person/1/ HTTP/1.1" 200 164
[04/Oct/2018 06:02:54] "GET /api/person/1/ HTTP/1.1" 200 164
[04/Oct/2018 06:03:59] "GET / HTTP/1.1" 200 2828
[04/Oct/2018 06:03:59] "GET /api/person/1/ HTTP/1.1" 200 164
[04/Oct/2018 06:03:59] "GET /api/person/1/ HTTP/1.1" 200 164
[04/Oct/2018 06:04:14] "GET / HTTP/1.1" 200 2828
[04/Oct/2018 06:04:14] "GET /api/person/1/ HTTP/1.1" 200 164
[04/Oct/2018 06:04:14] "GET /api/person/1/ HTTP/1.1" 200 164
[04/Oct/2018 06:04:53] "GET / HTTP/1.1" 200 2869
[04/Oct/2018 06:04:53] "GET /api/person/1/ HTTP/1.1" 200 164
[04/Oct/2018 06:04:53] "GET /api/person/1/ HTTP/1.1" 200 164
[04/Oct/2018 06:04:55] "GET / HTTP/1.1" 200 2869
[04/Oct/2018 06:04:55] "GET /api/person/1/ HTTP/1.1" 200 164
[04/Oct/2018 06:04:56] "GET /api/person/1/ HTTP/1.1" 200 164
[04/Oct/2018 06:10:26] "GET / HTTP/1.1" 200 2581
[04/Oct/2018 06:10:26] "GET /api/person/1/ HTTP/1.1" 200 164
[04/Oct/2018 06:10:27] "GET /api/person/1/ HTTP/1.1" 200 164
[04/Oct/2018 06:10:59] "GET / HTTP/1.1" 200 2591
[04/Oct/2018 06:11:00] "GET /api/person/1/ HTTP/1.1" 200 164
[04/Oct/2018 06:11:00] "GET /api/person/1/ HTTP/1.1" 200 164
[04/Oct/2018 06:11:29] "GET / HTTP/1.1" 200 2641
[04/Oct/2018 06:11:29] "GET /api/person/1/ HTTP/1.1" 200 164
[04/Oct/2018 06:11:29] "GET /api/person/1/ HTTP/1.1" 200 164
[04/Oct/2018 06:12:20] "GET /api/person/1/ HTTP/1.1" 200 164
[04/Oct/2018 06:12:21] "GET / HTTP/1.1" 200 2709
[04/Oct/2018 06:12:21] "GET /api/person/1/ HTTP/1.1" 200 164
[04/Oct/2018 06:15:08] "GET / HTTP/1.1" 200 2319
[04/Oct/2018 06:15:08] "GET /api/person/1/ HTTP/1.1" 200 164
[04/Oct/2018 06:15:08] "GET /api/person/1/ HTTP/1.1" 200 164
[04/Oct/2018 06:16:20] "GET / HTTP/1.1" 200 2583
[04/Oct/2018 06:16:20] "GET /api/person/1/ HTTP/1.1" 200 164
[04/Oct/2018 06:16:21] "GET /api/person/1/ HTTP/1.1" 200 164
[04/Oct/2018 14:08:31] "GET / HTTP/1.1" 200 2583
[04/Oct/2018 14:08:31] "GET /api/person/1/ HTTP/1.1" 200 164
[04/Oct/2018 14:08:42] "GET / HTTP/1.1" 200 2583
[04/Oct/2018 14:08:43] "GET /api/person/1/ HTTP/1.1" 200 164
[04/Oct/2018 14:08:47] "GET / HTTP/1.1" 200 2583
[04/Oct/2018 14:08:47] "GET /api/person/1/ HTTP/1.1" 200 164
Not Found: /image.jpeg
[04/Oct/2018 14:08:49] "GET /image.jpeg HTTP/1.1" 404 2546
Not Found: /image.jpeg
[04/Oct/2018 14:08:52] "GET /image.jpeg HTTP/1.1" 404 2546
[04/Oct/2018 14:08:53] "GET /image.jpg HTTP/1.1" 200 44969
[04/Oct/2018 14:09:08] "GET /image.jpg HTTP/1.1" 200 44969
[04/Oct/2018 14:09:09] "GET / HTTP/1.1" 200 2583
[04/Oct/2018 14:09:09] "GET /api/person/1/ HTTP/1.1" 200 164
[04/Oct/2018 14:09:09] "GET / HTTP/1.1" 200 2583
[04/Oct/2018 14:09:09] "GET /api/person/1/ HTTP/1.1" 200 164
[04/Oct/2018 14:14:51] "GET / HTTP/1.1" 200 2583
Not Found: /apple-touch-icon-precomposed.png
[04/Oct/2018 14:14:51] "GET /apple-touch-icon-precomposed.png HTTP/1.1" 404 2612
Not Found: /apple-touch-icon.png
[04/Oct/2018 14:14:51] "GET /apple-touch-icon.png HTTP/1.1" 404 2576
Not Found: /favicon.ico
[04/Oct/2018 14:14:51] "GET /favicon.ico HTTP/1.1" 404 2549
Not Found: /apple-touch-icon-precomposed.png
[04/Oct/2018 14:14:51] "GET /apple-touch-icon-precomposed.png HTTP/1.1" 404 2612
Not Found: /apple-touch-icon.png
[04/Oct/2018 14:14:51] "GET /apple-touch-icon.png HTTP/1.1" 404 2576
Not Found: /favicon.ico
[04/Oct/2018 14:14:51] "GET /favicon.ico HTTP/1.1" 404 2549
[04/Oct/2018 14:14:51] "GET / HTTP/1.1" 200 2583
Not Found: /apple-touch-icon-precomposed.png
[04/Oct/2018 14:14:51] "GET /apple-touch-icon-precomposed.png HTTP/1.1" 404 2612
Not Found: /apple-touch-icon.png
[04/Oct/2018 14:14:51] "GET /apple-touch-icon.png HTTP/1.1" 404 2576
Not Found: /favicon.ico
[04/Oct/2018 14:14:51] "GET /favicon.ico HTTP/1.1" 404 2549
Not Found: /apple-touch-icon-precomposed.png
[04/Oct/2018 14:14:51] "GET /apple-touch-icon-precomposed.png HTTP/1.1" 404 2612
Not Found: /apple-touch-icon.png
[04/Oct/2018 14:14:51] "GET /apple-touch-icon.png HTTP/1.1" 404 2576
Not Found: /favicon.ico
[04/Oct/2018 14:14:51] "GET /favicon.ico HTTP/1.1" 404 2549
[04/Oct/2018 14:29:56] "GET / HTTP/1.1" 200 2583
[04/Oct/2018 14:29:56] "GET /api/person/1/ HTTP/1.1" 200 164
Not Found: /apple-touch-icon-precomposed.png
[04/Oct/2018 14:29:56] "GET /apple-touch-icon-precomposed.png HTTP/1.1" 404 2612
Not Found: /apple-touch-icon.png
[04/Oct/2018 14:29:56] "GET /apple-touch-icon.png HTTP/1.1" 404 2576
[04/Oct/2018 14:30:10] "GET / HTTP/1.1" 200 2583
[04/Oct/2018 14:30:10] "GET /api/person/1/ HTTP/1.1" 200 164
[04/Oct/2018 14:30:13] "GET / HTTP/1.1" 200 2583
[04/Oct/2018 14:30:13] "GET /api/person/1/ HTTP/1.1" 200 164
[04/Oct/2018 14:30:14] "GET /admin/api/person/ HTTP/1.1" 200 4326
[04/Oct/2018 14:30:14] "GET /static/admin/css/base.css HTTP/1.1" 200 16225
[04/Oct/2018 14:30:14] "GET /admin/jsi18n/ HTTP/1.1" 200 3185
[04/Oct/2018 14:30:14] "GET /static/admin/css/changelists.css HTTP/1.1" 200 6170
[04/Oct/2018 14:30:14] "GET /static/admin/js/urlify.js HTTP/1.1" 200 8972
[04/Oct/2018 14:30:14] "GET /static/admin/js/vendor/jquery/jquery.js HTTP/1.1" 304 0
[04/Oct/2018 14:30:14] "GET /static/admin/js/vendor/xregexp/xregexp.js HTTP/1.1" 200 128820
[04/Oct/2018 14:30:14] "GET /static/admin/js/admin/RelatedObjectLookups.js HTTP/1.1" 304 0
[04/Oct/2018 14:30:14] "GET /static/admin/js/jquery.init.js HTTP/1.1" 304 0
[04/Oct/2018 14:30:14] "GET /static/admin/css/responsive.css HTTP/1.1" 304 0
[04/Oct/2018 14:30:14] "GET /static/admin/js/actions.js HTTP/1.1" 304 0
[04/Oct/2018 14:30:14] "GET /static/admin/js/prepopulate.js HTTP/1.1" 304 0
[04/Oct/2018 14:30:14] "GET /static/admin/js/core.js HTTP/1.1" 304 0
[04/Oct/2018 14:30:14] "GET /static/admin/css/fonts.css HTTP/1.1" 304 0
[04/Oct/2018 14:30:14] "GET /static/admin/img/tooltag-add.svg HTTP/1.1" 304 0
[04/Oct/2018 14:30:14] "GET /static/admin/fonts/Roboto-Regular-webfont.woff HTTP/1.1" 304 0
[04/Oct/2018 14:30:14] "GET /static/admin/fonts/Roboto-Light-webfont.woff HTTP/1.1" 304 0
[04/Oct/2018 14:30:14] "GET /static/admin/fonts/Roboto-Bold-webfont.woff HTTP/1.1" 304 0
[04/Oct/2018 14:30:14] "GET /admin/ HTTP/1.1" 200 4021
[04/Oct/2018 14:30:14] "GET /static/admin/css/dashboard.css HTTP/1.1" 304 0
[04/Oct/2018 14:30:14] "GET /static/admin/img/icon-changelink.svg HTTP/1.1" 304 0
[04/Oct/2018 14:30:14] "GET /static/admin/img/icon-addlink.svg HTTP/1.1" 200 331
[04/Oct/2018 14:30:15] "GET /admin/ HTTP/1.1" 200 4021
[04/Oct/2018 14:43:12] "GET / HTTP/1.1" 200 2583
Not Found: /apple-touch-icon-120x120-precomposed.png
[04/Oct/2018 14:43:12] "GET /apple-touch-icon-120x120-precomposed.png HTTP/1.1" 404 2636
Not Found: /apple-touch-icon-120x120.png
[04/Oct/2018 14:43:12] "GET /apple-touch-icon-120x120.png HTTP/1.1" 404 2600
Not Found: /apple-touch-icon-precomposed.png
[04/Oct/2018 14:43:12] "GET /apple-touch-icon-precomposed.png HTTP/1.1" 404 2612
Not Found: /apple-touch-icon.png
[04/Oct/2018 14:43:12] "GET /apple-touch-icon.png HTTP/1.1" 404 2576
Not Found: /favicon.ico
[04/Oct/2018 14:43:12] "GET /favicon.ico HTTP/1.1" 404 2549
Not Found: /apple-touch-icon-120x120-precomposed.png
[04/Oct/2018 14:43:12] "GET /apple-touch-icon-120x120-precomposed.png HTTP/1.1" 404 2636
Not Found: /apple-touch-icon-120x120.png
[04/Oct/2018 14:43:12] "GET /apple-touch-icon-120x120.png HTTP/1.1" 404 2600
Not Found: /apple-touch-icon-precomposed.png
[04/Oct/2018 14:43:12] "GET /apple-touch-icon-precomposed.png HTTP/1.1" 404 2612
Not Found: /apple-touch-icon.png
[04/Oct/2018 14:43:12] "GET /apple-touch-icon.png HTTP/1.1" 404 2576
Not Found: /favicon.ico
[04/Oct/2018 14:43:12] "GET /favicon.ico HTTP/1.1" 404 2549
[04/Oct/2018 18:41:17] "GET / HTTP/1.1" 200 2583
Not Found: /apple-touch-icon-120x120-precomposed.png
[04/Oct/2018 18:41:18] "GET /apple-touch-icon-120x120-precomposed.png HTTP/1.1" 404 2636
Not Found: /apple-touch-icon-120x120.png
[04/Oct/2018 18:41:18] "GET /apple-touch-icon-120x120.png HTTP/1.1" 404 2600
Not Found: /apple-touch-icon-precomposed.png
[04/Oct/2018 18:41:18] "GET /apple-touch-icon-precomposed.png HTTP/1.1" 404 2612
Not Found: /apple-touch-icon.png
[04/Oct/2018 18:41:18] "GET /apple-touch-icon.png HTTP/1.1" 404 2576
Not Found: /favicon.ico
[04/Oct/2018 18:41:18] "GET /favicon.ico HTTP/1.1" 404 2549
Not Found: /apple-touch-icon-120x120-precomposed.png
[04/Oct/2018 18:41:18] "GET /apple-touch-icon-120x120-precomposed.png HTTP/1.1" 404 2636
Not Found: /apple-touch-icon-120x120.png
[04/Oct/2018 18:41:18] "GET /apple-touch-icon-120x120.png HTTP/1.1" 404 2600
Not Found: /apple-touch-icon-precomposed.png
[04/Oct/2018 18:41:18] "GET /apple-touch-icon-precomposed.png HTTP/1.1" 404 2612
Not Found: /apple-touch-icon.png
[04/Oct/2018 18:41:18] "GET /apple-touch-icon.png HTTP/1.1" 404 2576
Not Found: /favicon.ico
[04/Oct/2018 18:41:18] "GET /favicon.ico HTTP/1.1" 404 2549
[04/Oct/2018 20:09:07] "GET / HTTP/1.1" 200 2583
[04/Oct/2018 20:09:07] "GET /api/person/1/ HTTP/1.1" 200 164
[04/Oct/2018 20:51:19] "GET / HTTP/1.1" 200 2583
[04/Oct/2018 21:25:47] "GET / HTTP/1.1" 200 2583
Not Found: /apple-touch-icon-120x120-precomposed.png
[04/Oct/2018 21:25:47] "GET /apple-touch-icon-120x120-precomposed.png HTTP/1.1" 404 2636
Not Found: /apple-touch-icon-120x120.png
[04/Oct/2018 21:25:47] "GET /apple-touch-icon-120x120.png HTTP/1.1" 404 2600
Not Found: /apple-touch-icon-precomposed.png
[04/Oct/2018 21:25:47] "GET /apple-touch-icon-precomposed.png HTTP/1.1" 404 2612
Not Found: /apple-touch-icon.png
[04/Oct/2018 21:25:47] "GET /apple-touch-icon.png HTTP/1.1" 404 2576
Not Found: /favicon.ico
[04/Oct/2018 21:25:47] "GET /favicon.ico HTTP/1.1" 404 2549
Not Found: /apple-touch-icon-120x120-precomposed.png
[04/Oct/2018 21:25:47] "GET /apple-touch-icon-120x120-precomposed.png HTTP/1.1" 404 2636
Not Found: /apple-touch-icon-120x120.png
[04/Oct/2018 21:25:47] "GET /apple-touch-icon-120x120.png HTTP/1.1" 404 2600
Not Found: /apple-touch-icon-precomposed.png
[04/Oct/2018 21:25:47] "GET /apple-touch-icon-precomposed.png HTTP/1.1" 404 2612
Not Found: /apple-touch-icon.png
[04/Oct/2018 21:25:47] "GET /apple-touch-icon.png HTTP/1.1" 404 2576
Not Found: /favicon.ico
[04/Oct/2018 21:25:47] "GET /favicon.ico HTTP/1.1" 404 2549
[04/Oct/2018 22:07:15] "GET / HTTP/1.1" 200 2583
[04/Oct/2018 22:11:32] code 400, message Bad HTTP/0.9 request type ('\x16\x03\x03\x00\x9c\x01\x00\x00\x98\x03\x03[¶\x90\x14]\x93\x80²\x9c\x1a]©\x12/r')
[04/Oct/2018 22:11:32] You're accessing the development server over HTTPS, but it only supports HTTP.

[04/Oct/2018 22:11:33] code 400, message Bad HTTP/0.9 request type ('\x16\x03\x03\x00\x9c\x01\x00\x00\x98\x03\x03[¶\x90\x15å¯\x01M®É\x00\x17·<Ùs\x81(\x1a\x9d)DP')
[04/Oct/2018 22:11:33] You're accessing the development server over HTTPS, but it only supports HTTP.

[04/Oct/2018 22:55:10] "GET / HTTP/1.1" 200 2583
Not Found: /apple-touch-icon-120x120-precomposed.png
[04/Oct/2018 22:55:10] "GET /apple-touch-icon-120x120-precomposed.png HTTP/1.1" 404 2636
Not Found: /apple-touch-icon-120x120.png
[04/Oct/2018 22:55:10] "GET /apple-touch-icon-120x120.png HTTP/1.1" 404 2600
Not Found: /apple-touch-icon-precomposed.png
[04/Oct/2018 22:55:10] "GET /apple-touch-icon-precomposed.png HTTP/1.1" 404 2612
Not Found: /apple-touch-icon.png
[04/Oct/2018 22:55:10] "GET /apple-touch-icon.png HTTP/1.1" 404 2576
Not Found: /favicon.ico
[04/Oct/2018 22:55:10] "GET /favicon.ico HTTP/1.1" 404 2549
Not Found: /apple-touch-icon-120x120-precomposed.png
[04/Oct/2018 22:55:10] "GET /apple-touch-icon-120x120-precomposed.png HTTP/1.1" 404 2636
Not Found: /apple-touch-icon-120x120.png
[04/Oct/2018 22:55:10] "GET /apple-touch-icon-120x120.png HTTP/1.1" 404 2600
Not Found: /apple-touch-icon-precomposed.png
[04/Oct/2018 22:55:10] "GET /apple-touch-icon-precomposed.png HTTP/1.1" 404 2612
Not Found: /apple-touch-icon.png
[04/Oct/2018 22:55:10] "GET /apple-touch-icon.png HTTP/1.1" 404 2576
Not Found: /favicon.ico
[04/Oct/2018 22:55:10] "GET /favicon.ico HTTP/1.1" 404 2549
[05/Oct/2018 01:02:00] "GET / HTTP/1.1" 200 2583
Not Found: /apple-touch-icon-120x120-precomposed.png
[05/Oct/2018 01:02:01] "GET /apple-touch-icon-120x120-precomposed.png HTTP/1.1" 404 2636
Not Found: /apple-touch-icon-120x120.png
[05/Oct/2018 01:02:01] "GET /apple-touch-icon-120x120.png HTTP/1.1" 404 2600
Not Found: /apple-touch-icon-precomposed.png
[05/Oct/2018 01:02:02] "GET /apple-touch-icon-precomposed.png HTTP/1.1" 404 2612
Not Found: /apple-touch-icon.png
[05/Oct/2018 01:02:02] "GET /apple-touch-icon.png HTTP/1.1" 404 2576
Not Found: /favicon.ico
[05/Oct/2018 01:02:02] "GET /favicon.ico HTTP/1.1" 404 2549
Not Found: /apple-touch-icon-120x120-precomposed.png
[05/Oct/2018 01:02:03] "GET /apple-touch-icon-120x120-precomposed.png HTTP/1.1" 404 2636
Not Found: /apple-touch-icon-120x120.png
[05/Oct/2018 01:02:03] "GET /apple-touch-icon-120x120.png HTTP/1.1" 404 2600
Not Found: /apple-touch-icon-precomposed.png
[05/Oct/2018 01:02:03] "GET /apple-touch-icon-precomposed.png HTTP/1.1" 404 2612
Not Found: /apple-touch-icon.png
[05/Oct/2018 01:02:03] "GET /apple-touch-icon.png HTTP/1.1" 404 2576
Not Found: /favicon.ico
[05/Oct/2018 01:02:04] "GET /favicon.ico HTTP/1.1" 404 2549
[05/Oct/2018 13:55:19] "GET / HTTP/1.1" 200 2583
Not Found: /apple-touch-icon-120x120-precomposed.png
[05/Oct/2018 13:55:20] "GET /apple-touch-icon-120x120-precomposed.png HTTP/1.1" 404 2636
Not Found: /apple-touch-icon-120x120.png
[05/Oct/2018 13:55:21] "GET /apple-touch-icon-120x120.png HTTP/1.1" 404 2600
Not Found: /apple-touch-icon-precomposed.png
[05/Oct/2018 13:55:21] "GET /apple-touch-icon-precomposed.png HTTP/1.1" 404 2612
Not Found: /apple-touch-icon.png
[05/Oct/2018 13:55:21] "GET /apple-touch-icon.png HTTP/1.1" 404 2576
Not Found: /favicon.ico
[05/Oct/2018 13:55:22] "GET /favicon.ico HTTP/1.1" 404 2549
Not Found: /apple-touch-icon-120x120-precomposed.png
[05/Oct/2018 13:55:22] "GET /apple-touch-icon-120x120-precomposed.png HTTP/1.1" 404 2636
Not Found: /apple-touch-icon-120x120.png
[05/Oct/2018 13:55:22] "GET /apple-touch-icon-120x120.png HTTP/1.1" 404 2600
Not Found: /apple-touch-icon-precomposed.png
[05/Oct/2018 13:55:23] "GET /apple-touch-icon-precomposed.png HTTP/1.1" 404 2612
Not Found: /apple-touch-icon.png
[05/Oct/2018 13:55:23] "GET /apple-touch-icon.png HTTP/1.1" 404 2576
Not Found: /favicon.ico
[05/Oct/2018 13:55:23] "GET /favicon.ico HTTP/1.1" 404 2549
[05/Oct/2018 14:57:24] "GET / HTTP/1.1" 200 2583
Not Found: /apple-touch-icon-120x120-precomposed.png
[05/Oct/2018 14:57:24] "GET /apple-touch-icon-120x120-precomposed.png HTTP/1.1" 404 2636
Not Found: /apple-touch-icon-120x120.png
[05/Oct/2018 14:57:24] "GET /apple-touch-icon-120x120.png HTTP/1.1" 404 2600
Not Found: /apple-touch-icon-precomposed.png
[05/Oct/2018 14:57:24] "GET /apple-touch-icon-precomposed.png HTTP/1.1" 404 2612
Not Found: /apple-touch-icon.png
[05/Oct/2018 14:57:24] "GET /apple-touch-icon.png HTTP/1.1" 404 2576
Not Found: /favicon.ico
[05/Oct/2018 14:57:25] "GET /favicon.ico HTTP/1.1" 404 2549
Not Found: /apple-touch-icon-120x120-precomposed.png
[05/Oct/2018 14:57:25] "GET /apple-touch-icon-120x120-precomposed.png HTTP/1.1" 404 2636
Not Found: /apple-touch-icon-120x120.png
[05/Oct/2018 14:57:25] "GET /apple-touch-icon-120x120.png HTTP/1.1" 404 2600
Not Found: /apple-touch-icon-precomposed.png
[05/Oct/2018 14:57:25] "GET /apple-touch-icon-precomposed.png HTTP/1.1" 404 2612
Not Found: /apple-touch-icon.png
[05/Oct/2018 14:57:25] "GET /apple-touch-icon.png HTTP/1.1" 404 2576
Not Found: /favicon.ico
[05/Oct/2018 14:57:26] "GET /favicon.ico HTTP/1.1" 404 2549
[05/Oct/2018 16:09:39] "GET / HTTP/1.1" 200 2583
[05/Oct/2018 16:09:39] "GET /api/person/1/ HTTP/1.1" 200 164
Not Found: /favicon.ico
[05/Oct/2018 16:09:39] "GET /favicon.ico HTTP/1.1" 404 2549
Invalid HTTP_HOST header: 'instance:8000'. You may need to add 'instance' to ALLOWED_HOSTS.
Bad Request: /
[05/Oct/2018 16:17:07] "GET / HTTP/1.0" 400 60566
[05/Oct/2018 17:25:28] "GET / HTTP/1.1" 200 2583
Not Found: /apple-touch-icon-120x120-precomposed.png
[05/Oct/2018 17:25:28] "GET /apple-touch-icon-120x120-precomposed.png HTTP/1.1" 404 2636
Not Found: /apple-touch-icon-120x120.png
[05/Oct/2018 17:25:28] "GET /apple-touch-icon-120x120.png HTTP/1.1" 404 2600
Not Found: /apple-touch-icon-precomposed.png
[05/Oct/2018 17:25:28] "GET /apple-touch-icon-precomposed.png HTTP/1.1" 404 2612
Not Found: /apple-touch-icon.png
[05/Oct/2018 17:25:28] "GET /apple-touch-icon.png HTTP/1.1" 404 2576
Not Found: /favicon.ico
[05/Oct/2018 17:25:29] "GET /favicon.ico HTTP/1.1" 404 2549
Not Found: /apple-touch-icon-120x120-precomposed.png
[05/Oct/2018 17:25:29] "GET /apple-touch-icon-120x120-precomposed.png HTTP/1.1" 404 2636
Not Found: /apple-touch-icon-120x120.png
[05/Oct/2018 17:25:29] "GET /apple-touch-icon-120x120.png HTTP/1.1" 404 2600
Not Found: /apple-touch-icon-precomposed.png
[05/Oct/2018 17:25:29] "GET /apple-touch-icon-precomposed.png HTTP/1.1" 404 2612
Not Found: /apple-touch-icon.png
[05/Oct/2018 17:25:29] "GET /apple-touch-icon.png HTTP/1.1" 404 2576
Not Found: /favicon.ico
[05/Oct/2018 17:25:29] "GET /favicon.ico HTTP/1.1" 404 2549
[05/Oct/2018 21:18:35] "GET / HTTP/1.1" 200 2583
[05/Oct/2018 21:38:16] "GET / HTTP/1.1" 200 2583
[05/Oct/2018 21:38:16] "GET /api/person/1/ HTTP/1.1" 200 164
[05/Oct/2018 21:46:45] "GET / HTTP/1.1" 200 2657
Not Found: /apple-touch-icon-120x120-precomposed.png
[05/Oct/2018 21:46:45] "GET /apple-touch-icon-120x120-precomposed.png HTTP/1.1" 404 2636
Not Found: /apple-touch-icon-120x120.png
[05/Oct/2018 21:46:45] "GET /apple-touch-icon-120x120.png HTTP/1.1" 404 2600
Not Found: /apple-touch-icon-precomposed.png
[05/Oct/2018 21:46:45] "GET /apple-touch-icon-precomposed.png HTTP/1.1" 404 2612
Not Found: /apple-touch-icon.png
[05/Oct/2018 21:46:45] "GET /apple-touch-icon.png HTTP/1.1" 404 2576
Not Found: /favicon.ico
[05/Oct/2018 21:46:45] "GET /favicon.ico HTTP/1.1" 404 2549
Not Found: /apple-touch-icon-120x120-precomposed.png
[05/Oct/2018 21:46:45] "GET /apple-touch-icon-120x120-precomposed.png HTTP/1.1" 404 2636
Not Found: /apple-touch-icon-120x120.png
[05/Oct/2018 21:46:45] "GET /apple-touch-icon-120x120.png HTTP/1.1" 404 2600
Not Found: /apple-touch-icon-precomposed.png
[05/Oct/2018 21:46:45] "GET /apple-touch-icon-precomposed.png HTTP/1.1" 404 2612
Not Found: /apple-touch-icon.png
[05/Oct/2018 21:46:45] "GET /apple-touch-icon.png HTTP/1.1" 404 2576
Not Found: /favicon.ico
[05/Oct/2018 21:46:45] "GET /favicon.ico HTTP/1.1" 404 2549
[05/Oct/2018 21:46:53] "GET / HTTP/1.1" 200 2657
[05/Oct/2018 21:46:53] "GET /api/person/1/ HTTP/1.1" 200 164
[05/Oct/2018 21:47:20] "GET / HTTP/1.1" 200 2657
[05/Oct/2018 21:47:20] "GET /api/person/1/ HTTP/1.1" 200 164
[05/Oct/2018 21:47:22] "GET / HTTP/1.1" 200 2657
[05/Oct/2018 21:47:22] "GET /api/person/1/ HTTP/1.1" 200 164
[05/Oct/2018 21:47:23] "GET /admin/api/person/ HTTP/1.1" 200 4326
[05/Oct/2018 21:47:23] "GET /static/admin/css/base.css HTTP/1.1" 304 0
[05/Oct/2018 21:47:23] "GET /static/admin/fonts/Roboto-Light-webfont.woff HTTP/1.1" 304 0
[05/Oct/2018 21:47:23] "GET /admin/ HTTP/1.1" 200 4021
[05/Oct/2018 21:47:23] "GET /static/admin/css/dashboard.css HTTP/1.1" 304 0
[05/Oct/2018 21:47:23] "GET /static/admin/css/fonts.css HTTP/1.1" 200 423
[05/Oct/2018 21:47:23] "GET /static/admin/css/responsive.css HTTP/1.1" 200 17976
[05/Oct/2018 21:47:23] "GET /static/admin/img/icon-addlink.svg HTTP/1.1" 200 331
[05/Oct/2018 21:47:23] "GET /static/admin/img/icon-changelink.svg HTTP/1.1" 200 380
[05/Oct/2018 21:47:23] "GET /static/admin/fonts/Roboto-Regular-webfont.woff HTTP/1.1" 200 80304
[05/Oct/2018 21:47:23] "GET /static/admin/fonts/Roboto-Bold-webfont.woff HTTP/1.1" 200 82564
[05/Oct/2018 21:47:23] "GET /admin/ HTTP/1.1" 200 4021
[05/Oct/2018 21:47:25] "GET /admin/api/person/ HTTP/1.1" 200 4326
[05/Oct/2018 21:47:25] "GET /static/admin/css/changelists.css HTTP/1.1" 200 6170
[05/Oct/2018 21:47:25] "GET /admin/jsi18n/ HTTP/1.1" 200 3185
[05/Oct/2018 21:47:25] "GET /static/admin/js/jquery.init.js HTTP/1.1" 200 363
[05/Oct/2018 21:47:25] "GET /static/admin/js/admin/RelatedObjectLookups.js HTTP/1.1" 200 6918
[05/Oct/2018 21:47:25] "GET /static/admin/js/core.js HTTP/1.1" 304 0
[05/Oct/2018 21:47:25] "GET /static/admin/js/prepopulate.js HTTP/1.1" 304 0
[05/Oct/2018 21:47:25] "GET /static/admin/js/actions.js HTTP/1.1" 304 0
[05/Oct/2018 21:47:25] "GET /static/admin/js/vendor/jquery/jquery.js HTTP/1.1" 304 0
[05/Oct/2018 21:47:25] "GET /static/admin/js/urlify.js HTTP/1.1" 304 0
[05/Oct/2018 21:47:25] "GET /static/admin/js/vendor/xregexp/xregexp.js HTTP/1.1" 200 128820
[05/Oct/2018 21:47:25] "GET /static/admin/img/tooltag-add.svg HTTP/1.1" 200 331
[05/Oct/2018 21:47:40] "GET /admin/api/person/1/change/ HTTP/1.1" 200 6707
[05/Oct/2018 21:47:40] "GET /static/admin/css/forms.css HTTP/1.1" 200 8505
[05/Oct/2018 21:47:40] "GET /static/admin/js/change_form.js HTTP/1.1" 200 712
[05/Oct/2018 21:47:40] "GET /static/admin/js/prepopulate_init.js HTTP/1.1" 200 495
[05/Oct/2018 21:47:40] "GET /admin/jsi18n/ HTTP/1.1" 200 3185
[05/Oct/2018 21:47:40] "GET /static/admin/css/widgets.css HTTP/1.1" 200 10340
[05/Oct/2018 21:49:25] "POST /admin/api/person/1/change/ HTTP/1.1" 302 0
[05/Oct/2018 21:49:25] "GET /admin/api/person/ HTTP/1.1" 200 4516
[05/Oct/2018 21:49:25] "GET /admin/jsi18n/ HTTP/1.1" 200 3185
[05/Oct/2018 21:49:25] "GET /static/admin/img/icon-yes.svg HTTP/1.1" 200 436
[05/Oct/2018 21:49:35] "GET / HTTP/1.1" 200 2657
[05/Oct/2018 21:49:35] "GET /api/person/1/ HTTP/1.1" 200 498
[05/Oct/2018 21:49:40] "GET /api/person/1/ HTTP/1.1" 200 498
[05/Oct/2018 21:49:40] "GET / HTTP/1.1" 200 2657
[05/Oct/2018 21:51:15] "GET / HTTP/1.1" 200 2658
[05/Oct/2018 21:51:15] "GET /api/person/1/ HTTP/1.1" 200 498
[05/Oct/2018 21:51:15] "GET /api/person/1/ HTTP/1.1" 200 498
[05/Oct/2018 21:51:16] "GET / HTTP/1.1" 200 2658
[05/Oct/2018 21:51:16] "GET /api/person/1/ HTTP/1.1" 200 498
[05/Oct/2018 21:51:16] "GET /api/person/1/ HTTP/1.1" 200 498
[05/Oct/2018 21:51:19] "GET / HTTP/1.1" 200 2658
[05/Oct/2018 21:51:19] "GET /api/person/1/ HTTP/1.1" 200 498
[05/Oct/2018 21:51:20] "GET /api/person/1/ HTTP/1.1" 200 498
[05/Oct/2018 21:56:29] "GET / HTTP/1.1" 200 2658
[05/Oct/2018 21:56:29] "GET /api/person/1/ HTTP/1.1" 200 498
[05/Oct/2018 21:56:59] "GET /image.jpg HTTP/1.1" 200 44969
[05/Oct/2018 21:59:05] "GET /image.jpg HTTP/1.1" 200 44969
